Workbook

Sheet PENGISIAN
E2: Laporan Pengisian Bahan Bakar Solar Tambang
E3: Note : Total Pemakaian Perhari Pada Header (Liter)
B5: Perusahaan | C5: Jenis Alat | D5: Tipe Unit | E5: 1 | L5: 2 | S5: 3 | Z5: 4 | AG5: 5 | AN5: 6 | AU5: 7 | BB5: 8 | BI5: 9 | BP5: 10 | BW5: 11 | CD5: 12 | CK5: 13 | CR5: 14 | CY5: 15 | DF5: 16 | DM5: 17 | DT5: 18 | EA5: 19 | EH5: 20 | EO5: 21 | EV5: 22 | FC5: 23 | FJ5: 24 | FQ5: 25 | FX5: 26 | GE5: 27 | GL5: 28 | GS5: 29 | GZ5: 30 | HG5: 31
E6: PENGISIAN (LITER) | L6: PENGISIAN (LITER) | S6: PENGISIAN (LITER) | Z6: PENGISIAN (LITER) | AG6: PENGISIAN (LITER) | AN6: PENGISIAN (LITER) | AU6: PENGISIAN (LITER) | BB6: PENGISIAN (LITER) | BI6: PENGISIAN (LITER) | BP6: PENGISIAN (LITER) | BW6: PENGISIAN (LITER) | CD6: PENGISIAN (LITER) | CK6: PENGISIAN (LITER) | CR6: PENGISIAN (LITER) | CY6: PENGISIAN (LITER) | DF6: PENGISIAN (LITER) | DM6: PENGISIAN (LITER) | DT6: PENGISIAN (LITER) | EA6: PENGISIAN (LITER) | EH6: PENGISIAN (LITER) | EO6: PENGISIAN (LITER) | EV6: PENGISIAN (LITER) | FC6: PENGISIAN (LITER) | FJ6: PENGISIAN (LITER) | FQ6: PENGISIAN (LITER) | FX6: PENGISIAN (LITER) | GE6: PENGISIAN (LITER) | GL6: PENGISIAN (LITER) | GS6: PENGISIAN (LITER) | GZ6: PENGISIAN (LITER) | HG6: PENGISIAN (LITER) | HN6: Total (L) | HO6: Total (Jam) Ops | HP6: L/J
E7: P | F7: HM | G7: S | H7: HM | I7: L/Jam | J7: Jam Operasi | K7: Liter | L7: P | M7: HM | N7: S | O7: HM | P7: L/Jam | Q7: Jam Operasi | R7: Liter | S7: P | T7: HM | U7: S | V7: HM | W7: L/Jam | X7: Jam Operasi | Y7: Liter | Z7: P | AA7: HM | AB7: S | AC7: HM | AD7: L/Jam | AE7: Jam Operasi | AF7: Liter | AG7: P | AH7: HM | AI7: S | AJ7: HM | AK7: L/Jam | AL7: Jam Operasi | AM7: Liter | AN7: P | AO7: HM | AP7: S | AQ7: HM | AR7: L/Jam | AS7: Jam Operasi | AT7: Liter | AU7: P | AV7: HM | AW7: S | AX7: HM | AY7: L/Jam | AZ7: Jam Operasi | BA7: Liter | BB7: P | BC7: HM | BD7: S | BE7: HM | BF7: L/Jam | BG7: Jam Operasi | BH7: Liter | BI7: P | BJ7: HM | BK7: S | BL7: HM | BM7: L/Jam | BN7: Jam Operasi | BO7: Liter | BP7: P | BQ7: HM | BR7: S | BS7: HM | BT7: L/Jam | BU7: Jam Operasi | BV7: Liter | BW7: P | BX7: HM | BY7: S | BZ7: HM | CA7: L/Jam | CB7: Jam Operasi | CC7: Liter | CD7: P | CE7: HM | CF7: S | CG7: HM | CH7: L/Jam | CI7: Jam Operasi | CJ7: Liter | CK7: P | CL7: HM | CM7: S | CN7: HM | CO7: L/Jam | CP7: Jam Operasi | CQ7: Liter | CR7: P | CS7: HM | CT7: S | CU7: HM | CV7: L/Jam | CW7: Jam Operasi | CX7: Liter | CY7: P | CZ7: HM | DA7: S | DB7: HM | DC7: L/Jam | DD7: Jam Operasi | DE7: Liter | DF7: P | DG7: HM | DH7: S | DI7: HM | DJ7: L/Jam | DK7: Jam Operasi | DL7: Liter | DM7: P | DN7: HM | DO7: S | DP7: HM | DQ7: L/Jam | DR7: Jam Operasi | DS7: Liter | DT7: P | DU7: HM | DV7: S | DW7: HM | DX7: L/Jam | DY7: Jam Operasi | DZ7: Liter | EA7: P | EB7: HM | EC7: S | ED7: HM | EE7: L/Jam | EF7: Jam Operasi | EG7: Liter | EH7: P | EI7: HM | EJ7: S | EK7: HM | EL7: L/Jam | EM7: Jam Operasi | EN7: Liter | EO7: P | EP7: HM | EQ7: S | ER7: HM | ES7: L/Jam | ET7: Jam Operasi | EU7: Liter | EV7: P | EW7: HM | EX7: S | EY7: HM | EZ7: L/Jam | FA7: Jam Operasi | FB7: Liter | FC7: P | FD7: HM | FE7: S | FF7: HM | FG7: L/Jam | FH7: Jam Operasi | FI7: Liter | FJ7: P | FK7: HM | FL7: S | FM7: HM | FN7: L/Jam | FO7: Jam Operasi | FP7: Liter | FQ7: P | FR7: HM | FS7: S | FT7: HM | FU7: L/Jam | FV7: Jam Operasi | FW7: Liter | FX7: P | FY7: HM | FZ7: S | GA7: HM | GB7: L/Jam | GC7: Jam Operasi | GD7: Liter | GE7: P | GF7: HM | GG7: S | GH7: HM | GI7: L/Jam | GJ7: Jam Operasi | GK7: Liter | GL7: P | GM7: HM | GN7: S | GO7: HM | GP7: L/Jam | GQ7: Jam Operasi | GR7: Liter | GS7: P | GT7: HM | GU7: S | GV7: HM | GW7: L/Jam | GX7: Jam Operasi | GY7: Liter | GZ7: P | HA7: HM | HB7: S | HC7: HM | HD7: L/Jam | HE7: Jam Operasi | HF7: Liter | HG7: P | HH7: HM | HI7: S | HJ7: HM | HK7: L/Jam | HL7: Jam Operasi | HM7: Liter
B8: PT SEMEN PADANG | C8: Alat Muat | D8: EC 02 | E8: 0 | F8: 3090 | I8: =IFERROR(IF(J8>0,CALC!B8/J8,"-"),"-") -> - | J8: =IF(F8>0,IFERROR(IF(CALC!A8>0,CALC!A8-F8,"-"),"-"),"-") -> - | K8: =IF(SUM(E8,G8)>0,SUM(E8,G8),"-") -> - | L8: 0 | M8: 3090 | P8: =IFERROR(IF(Q8>0,CALC!D8/Q8,"-"),"-") -> - | Q8: =IF(M8>0,IFERROR(IF(CALC!C8>0,CALC!C8-M8,"-"),"-"),"-") -> - | R8: =IF(SUM(L8,N8)>0,SUM(L8,N8),"-") -> - | S8: 0 | T8: 3090 | W8: =IFERROR(IF(X8>0,CALC!F8/X8,"-"),"-") -> 7.24 | X8: =IF(T8>0,IFERROR(IF(CALC!E8>0,CALC!E8-T8,"-"),"-"),"-") -> 50 | Y8: =IF(SUM(S8,U8)>0,SUM(S8,U8),"-") -> - | Z8: 0 | AA8: 3090 | AB8: 362 | AC8: 3140 | AD8: =IFERROR(IF(AE8>0,CALC!H8/AE8,"-"),"-") -> 7.24 | AE8: =IF(AA8>0,IFERROR(IF(CALC!G8>0,CALC!G8-AA8,"-"),"-"),"-") -> 50 | AF8: =IF(SUM(Z8,AB8)>0,SUM(Z8,AB8),"-") -> 362 | AG8: 0 | AH8: 3140 | AK8: =IFERROR(IF(AL8>0,CALC!J8/AL8,"-"),"-") -> - | AL8: =IF(AH8>0,IFERROR(IF(CALC!I8>0,CALC!I8-AH8,"-"),"-"),"-") -> - | AM8: =IF(SUM(AG8,AI8)>0,SUM(AG8,AI8),"-") -> - | AR8: =IFERROR(IF(AS8>0,CALC!L8/AS8,"-"),"-") -> - | AS8: =IF(AO8>0,IFERROR(IF(CALC!K8>0,CALC!K8-AO8,"-"),"-"),"-") -> - | AT8: =IF(SUM(AN8,AP8)>0,SUM(AN8,AP8),"-") -> - | AY8: =IFERROR(IF(AZ8>0,CALC!N8/AZ8,"-"),"-") -> - | AZ8: =IF(AV8>0,IFERROR(IF(CALC!M8>0,CALC!M8-AV8,"-"),"-"),"-") -> - | BA8: =IF(SUM(AU8,AW8)>0,SUM(AU8,AW8),"-") -> - | BF8: =IFERROR(IF(BG8>0,CALC!P8/BG8,"-"),"-") -> - | BG8: =IF(BC8>0,IFERROR(IF(CALC!O8>0,CALC!O8-BC8,"-"),"-"),"-") -> - | BH8: =IF(SUM(BB8,BD8)>0,SUM(BB8,BD8),"-") -> - | BM8: =IFERROR(IF(BN8>0,CALC!R8/BN8,"-"),"-") -> - | BN8: =IF(BJ8>0,IFERROR(IF(CALC!Q8>0,CALC!Q8-BJ8,"-"),"-"),"-") -> - | BO8: =IF(SUM(BI8,BK8)>0,SUM(BI8,BK8),"-") -> - | BT8: =IFERROR(IF(BU8>0,CALC!T8/BU8,"-"),"-") -> - | BU8: =IF(BQ8>0,IFERROR(IF(CALC!S8>0,CALC!S8-BQ8,"-"),"-"),"-") -> - | BV8: =IF(SUM(BP8,BR8)>0,SUM(BP8,BR8),"-") -> - | CA8: =IFERROR(IF(CB8>0,CALC!V8/CB8,"-"),"-") -> - | CB8: =IF(BX8>0,IFERROR(IF(CALC!U8>0,CALC!U8-BX8,"-"),"-"),"-") -> - | CC8: =IF(SUM(BW8,BY8)>0,SUM(BW8,BY8),"-") -> - | CH8: =IFERROR(IF(CI8>0,CALC!X8/CI8,"-"),"-") -> - | CI8: =IF(CE8>0,IFERROR(IF(CALC!W8>0,CALC!W8-CE8,"-"),"-"),"-") -> - | CJ8: =IF(SUM(CD8,CF8)>0,SUM(CD8,CF8),"-") -> - | CO8: =IFERROR(IF(CP8>0,CALC!Z8/CP8,"-"),"-") -> - | CP8: =IF(CL8>0,IFERROR(IF(CALC!Y8>0,CALC!Y8-CL8,"-"),"-"),"-") -> - | CQ8: =IF(SUM(CK8,CM8)>0,SUM(CK8,CM8),"-") -> - | CV8: =IFERROR(IF(CW8>0,CALC!AB8/CW8,"-"),"-") -> - | CW8: =IF(CS8>0,IFERROR(IF(CALC!AA8>0,CALC!AA8-CS8,"-"),"-"),"-") -> - | CX8: =IF(SUM(CR8,CT8)>0,SUM(CR8,CT8),"-") -> - | DC8: =IFERROR(IF(DD8>0,CALC!AD8/DD8,"-"),"-") -> - | DD8: =IF(CZ8>0,IFERROR(IF(CALC!AC8>0,CALC!AC8-CZ8,"-"),"-"),"-") -> - | DE8: =IF(SUM(CY8,DA8)>0,SUM(CY8,DA8),"-") -> - | DJ8: =IFERROR(IF(DK8>0,CALC!AF8/DK8,"-"),"-") -> - | DK8: =IF(DG8>0,IFERROR(IF(CALC!AE8>0,CALC!AE8-DG8,"-"),"-"),"-") -> - | DL8: =IF(SUM(DF8,DH8)>0,SUM(DF8,DH8),"-") -> - | DQ8: =IFERROR(IF(DR8>0,CALC!AH8/DR8,"-"),"-") -> - | DR8: =IF(DN8>0,IFERROR(IF(CALC!AG8>0,CALC!AG8-DN8,"-"),"-"),"-") -> - | DS8: =IF(SUM(DM8,DO8)>0,SUM(DM8,DO8),"-") -> - | DX8: =IFERROR(IF(DY8>0,CALC!AJ8/DY8,"-"),"-") -> - | DY8: =IF(DU8>0,IFERROR(IF(CALC!AI8>0,CALC!AI8-DU8,"-"),"-"),"-") -> - | DZ8: =IF(SUM(DT8,DV8)>0,SUM(DT8,DV8),"-") -> - | EE8: =IFERROR(IF(EF8>0,CALC!AL8/EF8,"-"),"-") -> - | EF8: =IF(EB8>0,IFERROR(IF(CALC!AK8>0,CALC!AK8-EB8,"-"),"-"),"-") -> - | EG8: =IF(SUM(EA8,EC8)>0,SUM(EA8,EC8),"-") -> - | EL8: =IFERROR(IF(EM8>0,CALC!AN8/EM8,"-"),"-") -> - | EM8: =IF(EI8>0,IFERROR(IF(CALC!AM8>0,CALC!AM8-EI8,"-"),"-"),"-") -> - | EN8: =IF(SUM(EH8,EJ8)>0,SUM(EH8,EJ8),"-") -> - | ES8: =IFERROR(IF(ET8>0,CALC!AP8/ET8,"-"),"-") -> - | ET8: =IF(EP8>0,IFERROR(IF(CALC!AO8>0,CALC!AO8-EP8,"-"),"-"),"-") -> - | EU8: =IF(SUM(EO8,EQ8)>0,SUM(EO8,EQ8),"-") -> - | EZ8: =IFERROR(IF(FA8>0,CALC!AR8/FA8,"-"),"-") -> - | FA8: =IF(EW8>0,IFERROR(IF(CALC!AQ8>0,CALC!AQ8-EW8,"-"),"-"),"-") -> - | FB8: =IF(SUM(EV8,EX8)>0,SUM(EV8,EX8),"-") -> - | FG8: =IFERROR(IF(FH8>0,CALC!AT8/FH8,"-"),"-") -> - | FH8: =IF(FD8>0,IFERROR(IF(CALC!AS8>0,CALC!AS8-FD8,"-"),"-"),"-") -> - | FI8: =IF(SUM(FC8,FE8)>0,SUM(FC8,FE8),"-") -> - | FN8: =IFERROR(IF(FO8>0,CALC!AV8/FO8,"-"),"-") -> - | FO8: =IF(FK8>0,IFERROR(IF(CALC!AU8>0,CALC!AU8-FK8,"-"),"-"),"-") -> - | FP8: =IF(SUM(FJ8,FL8)>0,SUM(FJ8,FL8),"-") -> - | FU8: =IFERROR(IF(FV8>0,CALC!AX8/FV8,"-"),"-") -> - | FV8: =IF(FR8>0,IFERROR(IF(CALC!AW8>0,CALC!AW8-FR8,"-"),"-"),"-") -> - | FW8: =IF(SUM(FQ8,FS8)>0,SUM(FQ8,FS8),"-") -> - | GB8: =IFERROR(IF(GC8>0,CALC!AZ8/GC8,"-"),"-") -> - | GC8: =IF(FY8>0,IFERROR(IF(CALC!AY8>0,CALC!AY8-FY8,"-"),"-"),"-") -> - | GD8: =IF(SUM(FX8,FZ8)>0,SUM(FX8,FZ8),"-") -> - | GI8: =IFERROR(IF(GJ8>0,CALC!BB8/GJ8,"-"),"-") -> - | GJ8: =IF(GF8>0,IFERROR(IF(CALC!BA8>0,CALC!BA8-GF8,"-"),"-"),"-") -> - | GK8: =IF(SUM(GE8,GG8)>0,SUM(GE8,GG8),"-") -> - | GP8: =IFERROR(IF(GQ8>0,CALC!BD8/GQ8,"-"),"-") -> - | GQ8: =IF(GM8>0,IFERROR(IF(CALC!BC8>0,CALC!BC8-GM8,"-"),"-"),"-") -> - | GR8: =IF(SUM(GL8,GN8)>0,SUM(GL8,GN8),"-") -> - | GW8: =IFERROR(IF(GX8>0,CALC!BF8/GX8,"-"),"-") -> - | GX8: =IF(GT8>0,IFERROR(IF(CALC!BE8>0,CALC!BE8-GT8,"-"),"-"),"-") -> - | GY8: =IF(SUM(GS8,GU8)>0,SUM(GS8,GU8),"-") -> - | HD8: =IFERROR(IF(HE8>0,CALC!BH8/HE8,"-"),"-") -> - | HE8: =IF(HA8>0,IFERROR(IF(CALC!BG8>0,CALC!BG8-HA8,"-"),"-"),"-") -> - | HF8: =IF(SUM(GZ8,HB8)>0,SUM(GZ8,HB8),"-") -> - | HK8: =IFERROR(IF(HL8>0,CALC!BJ8/HL8,"-"),"-") -> - | HL8: =IF(HH8>0,IFERROR(IF(CALC!BI8>0,CALC!BI8-HH8,"-"),"-"),"-") -> - | HM8: =IF(SUM(HG8,HI8)>0,SUM(HG8,HI8),"-") -> - | HN8: =SUM(K8,R8,Y8,AF8,AM8,AT8,BA8,BH8,BO8,BV8,CC8,CJ8,CQ8,CX8,DE8,DL8,DS8,DZ8,EG8,EN8,EU8,FB8,FI8,FP8,FW8,GD8,GK8,GR8,GY8,HF8,HM8) -> 362 | HO8: =SUM(J8,Q8,X8,AE8,AL8,AS8,AZ8,BG8,BN8,BU8,CB8,CI8,CP8,CW8,DD8,DK8,DR8,DY8,EF8,EM8,ET8,FA8,FH8,FO8,FV8,GC8,GJ8,GQ8,GX8,HE8,HL8) -> 100 | HP8: =IFERROR(HN8/HO8,"") -> 3.62
D9: EC 03 | E9: 0 | F9: 29879 | I9: =IFERROR(IF(J9>0,CALC!B9/J9,"-"),"-") -> - | J9: =IF(F9>0,IFERROR(IF(CALC!A9>0,CALC!A9-F9,"-"),"-"),"-") -> - | K9: =IF(SUM(E9,G9)>0,SUM(E9,G9),"-") -> - | L9: 0 | M9: 29879 | P9: =IFERROR(IF(Q9>0,CALC!D9/Q9,"-"),"-") -> - | Q9: =IF(M9>0,IFERROR(IF(CALC!C9>0,CALC!C9-M9,"-"),"-"),"-") -> - | R9: =IF(SUM(L9,N9)>0,SUM(L9,N9),"-") -> - | S9: 0 | T9: 29879 | W9: =IFERROR(IF(X9>0,CALC!F9/X9,"-"),"-") -> - | X9: =IF(T9>0,IFERROR(IF(CALC!E9>0,CALC!E9-T9,"-"),"-"),"-") -> - | Y9: =IF(SUM(S9,U9)>0,SUM(S9,U9),"-") -> - | Z9: 0 | AA9: 29879 | AD9: =IFERROR(IF(AE9>0,CALC!H9/AE9,"-"),"-") -> - | AE9: =IF(AA9>0,IFERROR(IF(CALC!G9>0,CALC!G9-AA9,"-"),"-"),"-") -> - | AF9: =IF(SUM(Z9,AB9)>0,SUM(Z9,AB9),"-") -> - | AG9: 0 | AH9: 29879 | AK9: =IFERROR(IF(AL9>0,CALC!J9/AL9,"-"),"-") -> - | AL9: =IF(AH9>0,IFERROR(IF(CALC!I9>0,CALC!I9-AH9,"-"),"-"),"-") -> - | AM9: =IF(SUM(AG9,AI9)>0,SUM(AG9,AI9),"-") -> - | AR9: =IFERROR(IF(AS9>0,CALC!L9/AS9,"-"),"-") -> - | AS9: =IF(AO9>0,IFERROR(IF(CALC!K9>0,CALC!K9-AO9,"-"),"-"),"-") -> - | AT9: =IF(SUM(AN9,AP9)>0,SUM(AN9,AP9),"-") -> - | AY9: =IFERROR(IF(AZ9>0,CALC!N9/AZ9,"-"),"-") -> - | AZ9: =IF(AV9>0,IFERROR(IF(CALC!M9>0,CALC!M9-AV9,"-"),"-"),"-") -> - | BA9: =IF(SUM(AU9,AW9)>0,SUM(AU9,AW9),"-") -> - | BF9: =IFERROR(IF(BG9>0,CALC!P9/BG9,"-"),"-") -> - | BG9: =IF(BC9>0,IFERROR(IF(CALC!O9>0,CALC!O9-BC9,"-"),"-"),"-") -> - | BH9: =IF(SUM(BB9,BD9)>0,SUM(BB9,BD9),"-") -> - | BM9: =IFERROR(IF(BN9>0,CALC!R9/BN9,"-"),"-") -> - | BN9: =IF(BJ9>0,IFERROR(IF(CALC!Q9>0,CALC!Q9-BJ9,"-"),"-"),"-") -> - | BO9: =IF(SUM(BI9,BK9)>0,SUM(BI9,BK9),"-") -> - | BT9: =IFERROR(IF(BU9>0,CALC!T9/BU9,"-"),"-") -> - | BU9: =IF(BQ9>0,IFERROR(IF(CALC!S9>0,CALC!S9-BQ9,"-"),"-"),"-") -> - | BV9: =IF(SUM(BP9,BR9)>0,SUM(BP9,BR9),"-") -> - | CA9: =IFERROR(IF(CB9>0,CALC!V9/CB9,"-"),"-") -> - | CB9: =IF(BX9>0,IFERROR(IF(CALC!U9>0,CALC!U9-BX9,"-"),"-"),"-") -> - | CC9: =IF(SUM(BW9,BY9)>0,SUM(BW9,BY9),"-") -> - | CH9: =IFERROR(IF(CI9>0,CALC!X9/CI9,"-"),"-") -> - | CI9: =IF(CE9>0,IFERROR(IF(CALC!W9>0,CALC!W9-CE9,"-"),"-"),"-") -> - | CJ9: =IF(SUM(CD9,CF9)>0,SUM(CD9,CF9),"-") -> - | CO9: =IFERROR(IF(CP9>0,CALC!Z9/CP9,"-"),"-") -> - | CP9: =IF(CL9>0,IFERROR(IF(CALC!Y9>0,CALC!Y9-CL9,"-"),"-"),"-") -> - | CQ9: =IF(SUM(CK9,CM9)>0,SUM(CK9,CM9),"-") -> - | CV9: =IFERROR(IF(CW9>0,CALC!AB9/CW9,"-"),"-") -> - | CW9: =IF(CS9>0,IFERROR(IF(CALC!AA9>0,CALC!AA9-CS9,"-"),"-"),"-") -> - | CX9: =IF(SUM(CR9,CT9)>0,SUM(CR9,CT9),"-") -> - | DC9: =IFERROR(IF(DD9>0,CALC!AD9/DD9,"-"),"-") -> - | DD9: =IF(CZ9>0,IFERROR(IF(CALC!AC9>0,CALC!AC9-CZ9,"-"),"-"),"-") -> - | DE9: =IF(SUM(CY9,DA9)>0,SUM(CY9,DA9),"-") -> - | DJ9: =IFERROR(IF(DK9>0,CALC!AF9/DK9,"-"),"-") -> - | DK9: =IF(DG9>0,IFERROR(IF(CALC!AE9>0,CALC!AE9-DG9,"-"),"-"),"-") -> - | DL9: =IF(SUM(DF9,DH9)>0,SUM(DF9,DH9),"-") -> - | DQ9: =IFERROR(IF(DR9>0,CALC!AH9/DR9,"-"),"-") -> - | DR9: =IF(DN9>0,IFERROR(IF(CALC!AG9>0,CALC!AG9-DN9,"-"),"-"),"-") -> - | DS9: =IF(SUM(DM9,DO9)>0,SUM(DM9,DO9),"-") -> - | DX9: =IFERROR(IF(DY9>0,CALC!AJ9/DY9,"-"),"-") -> - | DY9: =IF(DU9>0,IFERROR(IF(CALC!AI9>0,CALC!AI9-DU9,"-"),"-"),"-") -> - | DZ9: =IF(SUM(DT9,DV9)>0,SUM(DT9,DV9),"-") -> - | EE9: =IFERROR(IF(EF9>0,CALC!AL9/EF9,"-"),"-") -> - | EF9: =IF(EB9>0,IFERROR(IF(CALC!AK9>0,CALC!AK9-EB9,"-"),"-"),"-") -> - | EG9: =IF(SUM(EA9,EC9)>0,SUM(EA9,EC9),"-") -> - | EL9: =IFERROR(IF(EM9>0,CALC!AN9/EM9,"-"),"-") -> - | EM9: =IF(EI9>0,IFERROR(IF(CALC!AM9>0,CALC!AM9-EI9,"-"),"-"),"-") -> - | EN9: =IF(SUM(EH9,EJ9)>0,SUM(EH9,EJ9),"-") -> - | ES9: =IFERROR(IF(ET9>0,CALC!AP9/ET9,"-"),"-") -> - | ET9: =IF(EP9>0,IFERROR(IF(CALC!AO9>0,CALC!AO9-EP9,"-"),"-"),"-") -> - | EU9: =IF(SUM(EO9,EQ9)>0,SUM(EO9,EQ9),"-") -> - | EZ9: =IFERROR(IF(FA9>0,CALC!AR9/FA9,"-"),"-") -> - | FA9: =IF(EW9>0,IFERROR(IF(CALC!AQ9>0,CALC!AQ9-EW9,"-"),"-"),"-") -> - | FB9: =IF(SUM(EV9,EX9)>0,SUM(EV9,EX9),"-") -> - | FG9: =IFERROR(IF(FH9>0,CALC!AT9/FH9,"-"),"-") -> - | FH9: =IF(FD9>0,IFERROR(IF(CALC!AS9>0,CALC!AS9-FD9,"-"),"-"),"-") -> - | FI9: =IF(SUM(FC9,FE9)>0,SUM(FC9,FE9),"-") -> - | FN9: =IFERROR(IF(FO9>0,CALC!AV9/FO9,"-"),"-") -> - | FO9: =IF(FK9>0,IFERROR(IF(CALC!AU9>0,CALC!AU9-FK9,"-"),"-"),"-") -> - | FP9: =IF(SUM(FJ9,FL9)>0,SUM(FJ9,FL9),"-") -> - | FU9: =IFERROR(IF(FV9>0,CALC!AX9/FV9,"-"),"-") -> - | FV9: =IF(FR9>0,IFERROR(IF(CALC!AW9>0,CALC!AW9-FR9,"-"),"-"),"-") -> - | FW9: =IF(SUM(FQ9,FS9)>0,SUM(FQ9,FS9),"-") -> - | GB9: =IFERROR(IF(GC9>0,CALC!AZ9/GC9,"-"),"-") -> - | GC9: =IF(FY9>0,IFERROR(IF(CALC!AY9>0,CALC!AY9-FY9,"-"),"-"),"-") -> - | GD9: =IF(SUM(FX9,FZ9)>0,SUM(FX9,FZ9),"-") -> - | GI9: =IFERROR(IF(GJ9>0,CALC!BB9/GJ9,"-"),"-") -> - | GJ9: =IF(GF9>0,IFERROR(IF(CALC!BA9>0,CALC!BA9-GF9,"-"),"-"),"-") -> - | GK9: =IF(SUM(GE9,GG9)>0,SUM(GE9,GG9),"-") -> - | GP9: =IFERROR(IF(GQ9>0,CALC!BD9/GQ9,"-"),"-") -> - | GQ9: =IF(GM9>0,IFERROR(IF(CALC!BC9>0,CALC!BC9-GM9,"-"),"-"),"-") -> - | GR9: =IF(SUM(GL9,GN9)>0,SUM(GL9,GN9),"-") -> - | GW9: =IFERROR(IF(GX9>0,CALC!BF9/GX9,"-"),"-") -> - | GX9: =IF(GT9>0,IFERROR(IF(CALC!BE9>0,CALC!BE9-GT9,"-"),"-"),"-") -> - | GY9: =IF(SUM(GS9,GU9)>0,SUM(GS9,GU9),"-") -> - | HD9: =IFERROR(IF(HE9>0,CALC!BH9/HE9,"-"),"-") -> - | HE9: =IF(HA9>0,IFERROR(IF(CALC!BG9>0,CALC!BG9-HA9,"-"),"-"),"-") -> - | HF9: =IF(SUM(GZ9,HB9)>0,SUM(GZ9,HB9),"-") -> - | HK9: =IFERROR(IF(HL9>0,CALC!BJ9/HL9,"-"),"-") -> - | HL9: =IF(HH9>0,IFERROR(IF(CALC!BI9>0,CALC!BI9-HH9,"-"),"-"),"-") -> - | HM9: =IF(SUM(HG9,HI9)>0,SUM(HG9,HI9),"-") -> - | HN9: =SUM(K9,R9,Y9,AF9,AM9,AT9,BA9,BH9,BO9,BV9,CC9,CJ9,CQ9,CX9,DE9,DL9,DS9,DZ9,EG9,EN9,EU9,FB9,FI9,FP9,FW9,GD9,GK9,GR9,GY9,HF9,HM9) -> 0 | HO9: =SUM(J9,Q9,X9,AE9,AL9,AS9,AZ9,BG9,BN9,BU9,CB9,CI9,CP9,CW9,DD9,DK9,DR9,DY9,EF9,EM9,ET9,FA9,FH9,FO9,FV9,GC9,GJ9,GQ9,GX9,HE9,HL9) -> 0 | HP9: =IFERROR(HN9/HO9,"")
D10: EH 06 | E10: 2333 | F10: 53106 | I10: =IFERROR(IF(J10>0,CALC!B10/J10,"-"),"-") -> 139.58824 | J10: =IF(F10>0,IFERROR(IF(CALC!A10>0,CALC!A10-F10,"-"),"-"),"-") -> 17 | K10: =IF(SUM(E10,G10)>0,SUM(E10,G10),"-") -> 2333 | L10: 2373 | M10: 53123 | P10: =IFERROR(IF(Q10>0,CALC!D10/Q10,"-"),"-") -> 132.10526 | Q10: =IF(M10>0,IFERROR(IF(CALC!C10>0,CALC!C10-M10,"-"),"-"),"-") -> 15.2 | R10: =IF(SUM(L10,N10)>0,SUM(L10,N10),"-") -> 2373 | S10: 2008 | T10: 53138.2 | W10: =IFERROR(IF(X10>0,CALC!F10/X10,"-"),"-") -> 132.86713 | X10: =IF(T10>0,IFERROR(IF(CALC!E10>0,CALC!E10-T10,"-"),"-"),"-") -> 14.3 | Y10: =IF(SUM(S10,U10)>0,SUM(S10,U10),"-") -> 2008 | Z10: 1900 | AA10: 53152.5 | AD10: =IFERROR(IF(AE10>0,CALC!H10/AE10,"-"),"-") -> - | AE10: =IF(AA10>0,IFERROR(IF(CALC!G10>0,CALC!G10-AA10,"-"),"-"),"-") -> - | AF10: =IF(SUM(Z10,AB10)>0,SUM(Z10,AB10),"-") -> 1900 | AG10: 0 | AH10: 53152.5 | AK10: =IFERROR(IF(AL10>0,CALC!J10/AL10,"-"),"-") -> - | AL10: =IF(AH10>0,IFERROR(IF(CALC!I10>0,CALC!I10-AH10,"-"),"-"),"-") -> - | AM10: =IF(SUM(AG10,AI10)>0,SUM(AG10,AI10),"-") -> - | AR10: =IFERROR(IF(AS10>0,CALC!L10/AS10,"-"),"-") -> - | AS10: =IF(AO10>0,IFERROR(IF(CALC!K10>0,CALC!K10-AO10,"-"),"-"),"-") -> - | AT10: =IF(SUM(AN10,AP10)>0,SUM(AN10,AP10),"-") -> - | AY10: =IFERROR(IF(AZ10>0,CALC!N10/AZ10,"-"),"-") -> - | AZ10: =IF(AV10>0,IFERROR(IF(CALC!M10>0,CALC!M10-AV10,"-"),"-"),"-") -> - | BA10: =IF(SUM(AU10,AW10)>0,SUM(AU10,AW10),"-") -> - | BF10: =IFERROR(IF(BG10>0,CALC!P10/BG10,"-"),"-") -> - | BG10: =IF(BC10>0,IFERROR(IF(CALC!O10>0,CALC!O10-BC10,"-"),"-"),"-") -> - | BH10: =IF(SUM(BB10,BD10)>0,SUM(BB10,BD10),"-") -> - | BM10: =IFERROR(IF(BN10>0,CALC!R10/BN10,"-"),"-") -> - | BN10: =IF(BJ10>0,IFERROR(IF(CALC!Q10>0,CALC!Q10-BJ10,"-"),"-"),"-") -> - | BO10: =IF(SUM(BI10,BK10)>0,SUM(BI10,BK10),"-") -> - | BT10: =IFERROR(IF(BU10>0,CALC!T10/BU10,"-"),"-") -> - | BU10: =IF(BQ10>0,IFERROR(IF(CALC!S10>0,CALC!S10-BQ10,"-"),"-"),"-") -> - | BV10: =IF(SUM(BP10,BR10)>0,SUM(BP10,BR10),"-") -> - | CA10: =IFERROR(IF(CB10>0,CALC!V10/CB10,"-"),"-") -> - | CB10: =IF(BX10>0,IFERROR(IF(CALC!U10>0,CALC!U10-BX10,"-"),"-"),"-") -> - | CC10: =IF(SUM(BW10,BY10)>0,SUM(BW10,BY10),"-") -> - | CH10: =IFERROR(IF(CI10>0,CALC!X10/CI10,"-"),"-") -> - | CI10: =IF(CE10>0,IFERROR(IF(CALC!W10>0,CALC!W10-CE10,"-"),"-"),"-") -> - | CJ10: =IF(SUM(CD10,CF10)>0,SUM(CD10,CF10),"-") -> - | CO10: =IFERROR(IF(CP10>0,CALC!Z10/CP10,"-"),"-") -> - | CP10: =IF(CL10>0,IFERROR(IF(CALC!Y10>0,CALC!Y10-CL10,"-"),"-"),"-") -> - | CQ10: =IF(SUM(CK10,CM10)>0,SUM(CK10,CM10),"-") -> - | CV10: =IFERROR(IF(CW10>0,CALC!AB10/CW10,"-"),"-") -> - | CW10: =IF(CS10>0,IFERROR(IF(CALC!AA10>0,CALC!AA10-CS10,"-"),"-"),"-") -> - | CX10: =IF(SUM(CR10,CT10)>0,SUM(CR10,CT10),"-") -> - | DC10: =IFERROR(IF(DD10>0,CALC!AD10/DD10,"-"),"-") -> - | DD10: =IF(CZ10>0,IFERROR(IF(CALC!AC10>0,CALC!AC10-CZ10,"-"),"-"),"-") -> - | DE10: =IF(SUM(CY10,DA10)>0,SUM(CY10,DA10),"-") -> - | DJ10: =IFERROR(IF(DK10>0,CALC!AF10/DK10,"-"),"-") -> - | DK10: =IF(DG10>0,IFERROR(IF(CALC!AE10>0,CALC!AE10-DG10,"-"),"-"),"-") -> - | DL10: =IF(SUM(DF10,DH10)>0,SUM(DF10,DH10),"-") -> - | DQ10: =IFERROR(IF(DR10>0,CALC!AH10/DR10,"-"),"-") -> - | DR10: =IF(DN10>0,IFERROR(IF(CALC!AG10>0,CALC!AG10-DN10,"-"),"-"),"-") -> - | DS10: =IF(SUM(DM10,DO10)>0,SUM(DM10,DO10),"-") -> - | DX10: =IFERROR(IF(DY10>0,CALC!AJ10/DY10,"-"),"-") -> - | DY10: =IF(DU10>0,IFERROR(IF(CALC!AI10>0,CALC!AI10-DU10,"-"),"-"),"-") -> - | DZ10: =IF(SUM(DT10,DV10)>0,SUM(DT10,DV10),"-") -> - | EE10: =IFERROR(IF(EF10>0,CALC!AL10/EF10,"-"),"-") -> - | EF10: =IF(EB10>0,IFERROR(IF(CALC!AK10>0,CALC!AK10-EB10,"-"),"-"),"-") -> - | EG10: =IF(SUM(EA10,EC10)>0,SUM(EA10,EC10),"-") -> - | EL10: =IFERROR(IF(EM10>0,CALC!AN10/EM10,"-"),"-") -> - | EM10: =IF(EI10>0,IFERROR(IF(CALC!AM10>0,CALC!AM10-EI10,"-"),"-"),"-") -> - | EN10: =IF(SUM(EH10,EJ10)>0,SUM(EH10,EJ10),"-") -> - | ES10: =IFERROR(IF(ET10>0,CALC!AP10/ET10,"-"),"-") -> - | ET10: =IF(EP10>0,IFERROR(IF(CALC!AO10>0,CALC!AO10-EP10,"-"),"-"),"-") -> - | EU10: =IF(SUM(EO10,EQ10)>0,SUM(EO10,EQ10),"-") -> - | EZ10: =IFERROR(IF(FA10>0,CALC!AR10/FA10,"-"),"-") -> - | FA10: =IF(EW10>0,IFERROR(IF(CALC!AQ10>0,CALC!AQ10-EW10,"-"),"-"),"-") -> - | FB10: =IF(SUM(EV10,EX10)>0,SUM(EV10,EX10),"-") -> - | FG10: =IFERROR(IF(FH10>0,CALC!AT10/FH10,"-"),"-") -> - | FH10: =IF(FD10>0,IFERROR(IF(CALC!AS10>0,CALC!AS10-FD10,"-"),"-"),"-") -> - | FI10: =IF(SUM(FC10,FE10)>0,SUM(FC10,FE10),"-") -> - | FN10: =IFERROR(IF(FO10>0,CALC!AV10/FO10,"-"),"-") -> - | FO10: =IF(FK10>0,IFERROR(IF(CALC!AU10>0,CALC!AU10-FK10,"-"),"-"),"-") -> - | FP10: =IF(SUM(FJ10,FL10)>0,SUM(FJ10,FL10),"-") -> - | FU10: =IFERROR(IF(FV10>0,CALC!AX10/FV10,"-"),"-") -> - | FV10: =IF(FR10>0,IFERROR(IF(CALC!AW10>0,CALC!AW10-FR10,"-"),"-"),"-") -> - | FW10: =IF(SUM(FQ10,FS10)>0,SUM(FQ10,FS10),"-") -> - | GB10: =IFERROR(IF(GC10>0,CALC!AZ10/GC10,"-"),"-") -> - | GC10: =IF(FY10>0,IFERROR(IF(CALC!AY10>0,CALC!AY10-FY10,"-"),"-"),"-") -> - | GD10: =IF(SUM(FX10,FZ10)>0,SUM(FX10,FZ10),"-") -> - | GI10: =IFERROR(IF(GJ10>0,CALC!BB10/GJ10,"-"),"-") -> - | GJ10: =IF(GF10>0,IFERROR(IF(CALC!BA10>0,CALC!BA10-GF10,"-"),"-"),"-") -> - | GK10: =IF(SUM(GE10,GG10)>0,SUM(GE10,GG10),"-") -> - | GP10: =IFERROR(IF(GQ10>0,CALC!BD10/GQ10,"-"),"-") -> - | GQ10: =IF(GM10>0,IFERROR(IF(CALC!BC10>0,CALC!BC10-GM10,"-"),"-"),"-") -> - | GR10: =IF(SUM(GL10,GN10)>0,SUM(GL10,GN10),"-") -> - | GW10: =IFERROR(IF(GX10>0,CALC!BF10/GX10,"-"),"-") -> - | GX10: =IF(GT10>0,IFERROR(IF(CALC!BE10>0,CALC!BE10-GT10,"-"),"-"),"-") -> - | GY10: =IF(SUM(GS10,GU10)>0,SUM(GS10,GU10),"-") -> - | HD10: =IFERROR(IF(HE10>0,CALC!BH10/HE10,"-"),"-") -> - | HE10: =IF(HA10>0,IFERROR(IF(CALC!BG10>0,CALC!BG10-HA10,"-"),"-"),"-") -> - | HF10: =IF(SUM(GZ10,HB10)>0,SUM(GZ10,HB10),"-") -> - | HK10: =IFERROR(IF(HL10>0,CALC!BJ10/HL10,"-"),"-") -> - | HL10: =IF(HH10>0,IFERROR(IF(CALC!BI10>0,CALC!BI10-HH10,"-"),"-"),"-") -> - | HM10: =IF(SUM(HG10,HI10)>0,SUM(HG10,HI10),"-") -> - | HN10: =SUM(K10,R10,Y10,AF10,AM10,AT10,BA10,BH10,BO10,BV10,CC10,CJ10,CQ10,CX10,DE10,DL10,DS10,DZ10,EG10,EN10,EU10,FB10,FI10,FP10,FW10,GD10,GK10,GR10,GY10,HF10,HM10) -> 8614 | HO10: =SUM(J10,Q10,X10,AE10,AL10,AS10,AZ10,BG10,BN10,BU10,CB10,CI10,CP10,CW10,DD10,DK10,DR10,DY10,EF10,EM10,ET10,FA10,FH10,FO10,FV10,GC10,GJ10,GQ10,GX10,HE10,HL10) -> 46.5 | HP10: =IFERROR(HN10/HO10,"") -> 185.24731
D11: LC 06 | I11: =IFERROR(IF(J11>0,CALC!B11/J11,"-"),"-") -> - | J11: =IF(F11>0,IFERROR(IF(CALC!A11>0,CALC!A11-F11,"-"),"-"),"-") -> - | K11: =IF(SUM(E11,G11)>0,SUM(E11,G11),"-") -> - | P11: =IFERROR(IF(Q11>0,CALC!D11/Q11,"-"),"-") -> - | Q11: =IF(M11>0,IFERROR(IF(CALC!C11>0,CALC!C11-M11,"-"),"-"),"-") -> - | R11: =IF(SUM(L11,N11)>0,SUM(L11,N11),"-") -> - | W11: =IFERROR(IF(X11>0,CALC!F11/X11,"-"),"-") -> - | X11: =IF(T11>0,IFERROR(IF(CALC!E11>0,CALC!E11-T11,"-"),"-"),"-") -> - | Y11: =IF(SUM(S11,U11)>0,SUM(S11,U11),"-") -> - | AD11: =IFERROR(IF(AE11>0,CALC!H11/AE11,"-"),"-") -> - | AE11: =IF(AA11>0,IFERROR(IF(CALC!G11>0,CALC!G11-AA11,"-"),"-"),"-") -> - | AF11: =IF(SUM(Z11,AB11)>0,SUM(Z11,AB11),"-") -> - | AK11: =IFERROR(IF(AL11>0,CALC!J11/AL11,"-"),"-") -> - | AL11: =IF(AH11>0,IFERROR(IF(CALC!I11>0,CALC!I11-AH11,"-"),"-"),"-") -> - | AM11: =IF(SUM(AG11,AI11)>0,SUM(AG11,AI11),"-") -> - | AR11: =IFERROR(IF(AS11>0,CALC!L11/AS11,"-"),"-") -> - | AS11: =IF(AO11>0,IFERROR(IF(CALC!K11>0,CALC!K11-AO11,"-"),"-"),"-") -> - | AT11: =IF(SUM(AN11,AP11)>0,SUM(AN11,AP11),"-") -> - | AY11: =IFERROR(IF(AZ11>0,CALC!N11/AZ11,"-"),"-") -> - | AZ11: =IF(AV11>0,IFERROR(IF(CALC!M11>0,CALC!M11-AV11,"-"),"-"),"-") -> - | BA11: =IF(SUM(AU11,AW11)>0,SUM(AU11,AW11),"-") -> - | BF11: =IFERROR(IF(BG11>0,CALC!P11/BG11,"-"),"-") -> - | BG11: =IF(BC11>0,IFERROR(IF(CALC!O11>0,CALC!O11-BC11,"-"),"-"),"-") -> - | BH11: =IF(SUM(BB11,BD11)>0,SUM(BB11,BD11),"-") -> - | BM11: =IFERROR(IF(BN11>0,CALC!R11/BN11,"-"),"-") -> - | BN11: =IF(BJ11>0,IFERROR(IF(CALC!Q11>0,CALC!Q11-BJ11,"-"),"-"),"-") -> - | BO11: =IF(SUM(BI11,BK11)>0,SUM(BI11,BK11),"-") -> - | BT11: =IFERROR(IF(BU11>0,CALC!T11/BU11,"-"),"-") -> - | BU11: =IF(BQ11>0,IFERROR(IF(CALC!S11>0,CALC!S11-BQ11,"-"),"-"),"-") -> - | BV11: =IF(SUM(BP11,BR11)>0,SUM(BP11,BR11),"-") -> - | CA11: =IFERROR(IF(CB11>0,CALC!V11/CB11,"-"),"-") -> - | CB11: =IF(BX11>0,IFERROR(IF(CALC!U11>0,CALC!U11-BX11,"-"),"-"),"-") -> - | CC11: =IF(SUM(BW11,BY11)>0,SUM(BW11,BY11),"-") -> - | CH11: =IFERROR(IF(CI11>0,CALC!X11/CI11,"-"),"-") -> - | CI11: =IF(CE11>0,IFERROR(IF(CALC!W11>0,CALC!W11-CE11,"-"),"-"),"-") -> - | CJ11: =IF(SUM(CD11,CF11)>0,SUM(CD11,CF11),"-") -> - | CO11: =IFERROR(IF(CP11>0,CALC!Z11/CP11,"-"),"-") -> - | CP11: =IF(CL11>0,IFERROR(IF(CALC!Y11>0,CALC!Y11-CL11,"-"),"-"),"-") -> - | CQ11: =IF(SUM(CK11,CM11)>0,SUM(CK11,CM11),"-") -> - | CV11: =IFERROR(IF(CW11>0,CALC!AB11/CW11,"-"),"-") -> - | CW11: =IF(CS11>0,IFERROR(IF(CALC!AA11>0,CALC!AA11-CS11,"-"),"-"),"-") -> - | CX11: =IF(SUM(CR11,CT11)>0,SUM(CR11,CT11),"-") -> - | DC11: =IFERROR(IF(DD11>0,CALC!AD11/DD11,"-"),"-") -> - | DD11: =IF(CZ11>0,IFERROR(IF(CALC!AC11>0,CALC!AC11-CZ11,"-"),"-"),"-") -> - | DE11: =IF(SUM(CY11,DA11)>0,SUM(CY11,DA11),"-") -> - | DJ11: =IFERROR(IF(DK11>0,CALC!AF11/DK11,"-"),"-") -> - | DK11: =IF(DG11>0,IFERROR(IF(CALC!AE11>0,CALC!AE11-DG11,"-"),"-"),"-") -> - | DL11: =IF(SUM(DF11,DH11)>0,SUM(DF11,DH11),"-") -> - | DQ11: =IFERROR(IF(DR11>0,CALC!AH11/DR11,"-"),"-") -> - | DR11: =IF(DN11>0,IFERROR(IF(CALC!AG11>0,CALC!AG11-DN11,"-"),"-"),"-") -> - | DS11: =IF(SUM(DM11,DO11)>0,SUM(DM11,DO11),"-") -> - | DX11: =IFERROR(IF(DY11>0,CALC!AJ11/DY11,"-"),"-") -> - | DY11: =IF(DU11>0,IFERROR(IF(CALC!AI11>0,CALC!AI11-DU11,"-"),"-"),"-") -> - | DZ11: =IF(SUM(DT11,DV11)>0,SUM(DT11,DV11),"-") -> - | EE11: =IFERROR(IF(EF11>0,CALC!AL11/EF11,"-"),"-") -> - | EF11: =IF(EB11>0,IFERROR(IF(CALC!AK11>0,CALC!AK11-EB11,"-"),"-"),"-") -> - | EG11: =IF(SUM(EA11,EC11)>0,SUM(EA11,EC11),"-") -> - | EL11: =IFERROR(IF(EM11>0,CALC!AN11/EM11,"-"),"-") -> - | EM11: =IF(EI11>0,IFERROR(IF(CALC!AM11>0,CALC!AM11-EI11,"-"),"-"),"-") -> - | EN11: =IF(SUM(EH11,EJ11)>0,SUM(EH11,EJ11),"-") -> - | ES11: =IFERROR(IF(ET11>0,CALC!AP11/ET11,"-"),"-") -> - | ET11: =IF(EP11>0,IFERROR(IF(CALC!AO11>0,CALC!AO11-EP11,"-"),"-"),"-") -> - | EU11: =IF(SUM(EO11,EQ11)>0,SUM(EO11,EQ11),"-") -> - | EZ11: =IFERROR(IF(FA11>0,CALC!AR11/FA11,"-"),"-") -> - | FA11: =IF(EW11>0,IFERROR(IF(CALC!AQ11>0,CALC!AQ11-EW11,"-"),"-"),"-") -> - | FB11: =IF(SUM(EV11,EX11)>0,SUM(EV11,EX11),"-") -> - | FG11: =IFERROR(IF(FH11>0,CALC!AT11/FH11,"-"),"-") -> - | FH11: =IF(FD11>0,IFERROR(IF(CALC!AS11>0,CALC!AS11-FD11,"-"),"-"),"-") -> - | FI11: =IF(SUM(FC11,FE11)>0,SUM(FC11,FE11),"-") -> - | FN11: =IFERROR(IF(FO11>0,CALC!AV11/FO11,"-"),"-") -> - | FO11: =IF(FK11>0,IFERROR(IF(CALC!AU11>0,CALC!AU11-FK11,"-"),"-"),"-") -> - | FP11: =IF(SUM(FJ11,FL11)>0,SUM(FJ11,FL11),"-") -> - | FU11: =IFERROR(IF(FV11>0,CALC!AX11/FV11,"-"),"-") -> - | FV11: =IF(FR11>0,IFERROR(IF(CALC!AW11>0,CALC!AW11-FR11,"-"),"-"),"-") -> - | FW11: =IF(SUM(FQ11,FS11)>0,SUM(FQ11,FS11),"-") -> - | GB11: =IFERROR(IF(GC11>0,CALC!AZ11/GC11,"-"),"-") -> - | GC11: =IF(FY11>0,IFERROR(IF(CALC!AY11>0,CALC!AY11-FY11,"-"),"-"),"-") -> - | GD11: =IF(SUM(FX11,FZ11)>0,SUM(FX11,FZ11),"-") -> - | GI11: =IFERROR(IF(GJ11>0,CALC!BB11/GJ11,"-"),"-") -> - | GJ11: =IF(GF11>0,IFERROR(IF(CALC!BA11>0,CALC!BA11-GF11,"-"),"-"),"-") -> - | GK11: =IF(SUM(GE11,GG11)>0,SUM(GE11,GG11),"-") -> - | GP11: =IFERROR(IF(GQ11>0,CALC!BD11/GQ11,"-"),"-") -> - | GQ11: =IF(GM11>0,IFERROR(IF(CALC!BC11>0,CALC!BC11-GM11,"-"),"-"),"-") -> - | GR11: =IF(SUM(GL11,GN11)>0,SUM(GL11,GN11),"-") -> - | GW11: =IFERROR(IF(GX11>0,CALC!BF11/GX11,"-"),"-") -> - | GX11: =IF(GT11>0,IFERROR(IF(CALC!BE11>0,CALC!BE11-GT11,"-"),"-"),"-") -> - | GY11: =IF(SUM(GS11,GU11)>0,SUM(GS11,GU11),"-") -> - | HD11: =IFERROR(IF(HE11>0,CALC!BH11/HE11,"-"),"-") -> - | HE11: =IF(HA11>0,IFERROR(IF(CALC!BG11>0,CALC!BG11-HA11,"-"),"-"),"-") -> - | HF11: =IF(SUM(GZ11,HB11)>0,SUM(GZ11,HB11),"-") -> - | HK11: =IFERROR(IF(HL11>0,CALC!BJ11/HL11,"-"),"-") -> - | HL11: =IF(HH11>0,IFERROR(IF(CALC!BI11>0,CALC!BI11-HH11,"-"),"-"),"-") -> - | HM11: =IF(SUM(HG11,HI11)>0,SUM(HG11,HI11),"-") -> - | HN11: =SUM(K11,R11,Y11,AF11,AM11,AT11,BA11,BH11,BO11,BV11,CC11,CJ11,CQ11,CX11,DE11,DL11,DS11,DZ11,EG11,EN11,EU11,FB11,FI11,FP11,FW11,GD11,GK11,GR11,GY11,HF11,HM11) -> 0 | HO11: =SUM(J11,Q11,X11,AE11,AL11,AS11,AZ11,BG11,BN11,BU11,CB11,CI11,CP11,CW11,DD11,DK11,DR11,DY11,EF11,EM11,ET11,FA11,FH11,FO11,FV11,GC11,GJ11,GQ11,GX11,HE11,HL11) -> 0 | HP11: =IFERROR(HN11/HO11,"")
D12: LK 15 | E12: 0 | F12: 25554.4 | I12: =IFERROR(IF(J12>0,CALC!B12/J12,"-"),"-") -> 51.860465 | J12: =IF(F12>0,IFERROR(IF(CALC!A12>0,CALC!A12-F12,"-"),"-"),"-") -> 12.9 | K12: =IF(SUM(E12,G12)>0,SUM(E12,G12),"-") -> - | L12: 669 | M12: 25567.3 | P12: =IFERROR(IF(Q12>0,CALC!D12/Q12,"-"),"-") -> - | Q12: =IF(M12>0,IFERROR(IF(CALC!C12>0,CALC!C12-M12,"-"),"-"),"-") -> - | R12: =IF(SUM(L12,N12)>0,SUM(L12,N12),"-") -> 669 | S12: 0 | T12: 25567.3 | W12: =IFERROR(IF(X12>0,CALC!F12/X12,"-"),"-") -> 87.179487 | X12: =IF(T12>0,IFERROR(IF(CALC!E12>0,CALC!E12-T12,"-"),"-"),"-") -> 3.9 | Y12: =IF(SUM(S12,U12)>0,SUM(S12,U12),"-") -> - | Z12: 340 | AA12: 25571.2 | AD12: =IFERROR(IF(AE12>0,CALC!H12/AE12,"-"),"-") -> 44.710744 | AE12: =IF(AA12>0,IFERROR(IF(CALC!G12>0,CALC!G12-AA12,"-"),"-"),"-") -> 12.1 | AF12: =IF(SUM(Z12,AB12)>0,SUM(Z12,AB12),"-") -> 340 | AG12: 541 | AH12: 25583.3 | AK12: =IFERROR(IF(AL12>0,CALC!J12/AL12,"-"),"-") -> - | AL12: =IF(AH12>0,IFERROR(IF(CALC!I12>0,CALC!I12-AH12,"-"),"-"),"-") -> - | AM12: =IF(SUM(AG12,AI12)>0,SUM(AG12,AI12),"-") -> 541 | AR12: =IFERROR(IF(AS12>0,CALC!L12/AS12,"-"),"-") -> - | AS12: =IF(AO12>0,IFERROR(IF(CALC!K12>0,CALC!K12-AO12,"-"),"-"),"-") -> - | AT12: =IF(SUM(AN12,AP12)>0,SUM(AN12,AP12),"-") -> - | AY12: =IFERROR(IF(AZ12>0,CALC!N12/AZ12,"-"),"-") -> - | AZ12: =IF(AV12>0,IFERROR(IF(CALC!M12>0,CALC!M12-AV12,"-"),"-"),"-") -> - | BA12: =IF(SUM(AU12,AW12)>0,SUM(AU12,AW12),"-") -> - | BF12: =IFERROR(IF(BG12>0,CALC!P12/BG12,"-"),"-") -> - | BG12: =IF(BC12>0,IFERROR(IF(CALC!O12>0,CALC!O12-BC12,"-"),"-"),"-") -> - | BH12: =IF(SUM(BB12,BD12)>0,SUM(BB12,BD12),"-") -> - | BM12: =IFERROR(IF(BN12>0,CALC!R12/BN12,"-"),"-") -> - | BN12: - | BO12: =IF(SUM(BI12,BK12)>0,SUM(BI12,BK12),"-") -> - | BT12: =IFERROR(IF(BU12>0,CALC!T12/BU12,"-"),"-") -> - | BU12: =IF(BQ12>0,IFERROR(IF(CALC!S12>0,CALC!S12-BQ12,"-"),"-"),"-") -> - | BV12: =IF(SUM(BP12,BR12)>0,SUM(BP12,BR12),"-") -> - | CA12: =IFERROR(IF(CB12>0,CALC!V12/CB12,"-"),"-") -> - | CB12: =IF(BX12>0,IFERROR(IF(CALC!U12>0,CALC!U12-BX12,"-"),"-"),"-") -> - | CC12: =IF(SUM(BW12,BY12)>0,SUM(BW12,BY12),"-") -> - | CH12: =IFERROR(IF(CI12>0,CALC!X12/CI12,"-"),"-") -> - | CI12: =IF(CE12>0,IFERROR(IF(CALC!W12>0,CALC!W12-CE12,"-"),"-"),"-") -> - | CJ12: =IF(SUM(CD12,CF12)>0,SUM(CD12,CF12),"-") -> - | CO12: =IFERROR(IF(CP12>0,CALC!Z12/CP12,"-"),"-") -> - | CP12: =IF(CL12>0,IFERROR(IF(CALC!Y12>0,CALC!Y12-CL12,"-"),"-"),"-") -> - | CQ12: =IF(SUM(CK12,CM12)>0,SUM(CK12,CM12),"-") -> - | CV12: =IFERROR(IF(CW12>0,CALC!AB12/CW12,"-"),"-") -> - | CW12: =IF(CS12>0,IFERROR(IF(CALC!AA12>0,CALC!AA12-CS12,"-"),"-"),"-") -> - | CX12: =IF(SUM(CR12,CT12)>0,SUM(CR12,CT12),"-") -> - | DC12: =IFERROR(IF(DD12>0,CALC!AD12/DD12,"-"),"-") -> - | DD12: =IF(CZ12>0,IFERROR(IF(CALC!AC12>0,CALC!AC12-CZ12,"-"),"-"),"-") -> - | DE12: =IF(SUM(CY12,DA12)>0,SUM(CY12,DA12),"-") -> - | DJ12: =IFERROR(IF(DK12>0,CALC!AF12/DK12,"-"),"-") -> - | DK12: =IF(DG12>0,IFERROR(IF(CALC!AE12>0,CALC!AE12-DG12,"-"),"-"),"-") -> - | DL12: =IF(SUM(DF12,DH12)>0,SUM(DF12,DH12),"-") -> - | DQ12: =IFERROR(IF(DR12>0,CALC!AH12/DR12,"-"),"-") -> - | DR12: =IF(DN12>0,IFERROR(IF(CALC!AG12>0,CALC!AG12-DN12,"-"),"-"),"-") -> - | DS12: =IF(SUM(DM12,DO12)>0,SUM(DM12,DO12),"-") -> - | DX12: =IFERROR(IF(DY12>0,CALC!AJ12/DY12,"-"),"-") -> - | DY12: =IF(DU12>0,IFERROR(IF(CALC!AI12>0,CALC!AI12-DU12,"-"),"-"),"-") -> - | DZ12: =IF(SUM(DT12,DV12)>0,SUM(DT12,DV12),"-") -> - | EE12: =IFERROR(IF(EF12>0,CALC!AL12/EF12,"-"),"-") -> - | EF12: =IF(EB12>0,IFERROR(IF(CALC!AK12>0,CALC!AK12-EB12,"-"),"-"),"-") -> - | EG12: =IF(SUM(EA12,EC12)>0,SUM(EA12,EC12),"-") -> - | EL12: =IFERROR(IF(EM12>0,CALC!AN12/EM12,"-"),"-") -> - | EM12: =IF(EI12>0,IFERROR(IF(CALC!AM12>0,CALC!AM12-EI12,"-"),"-"),"-") -> - | EN12: =IF(SUM(EH12,EJ12)>0,SUM(EH12,EJ12),"-") -> - | ES12: =IFERROR(IF(ET12>0,CALC!AP12/ET12,"-"),"-") -> - | ET12: =IF(EP12>0,IFERROR(IF(CALC!AO12>0,CALC!AO12-EP12,"-"),"-"),"-") -> - | EU12: =IF(SUM(EO12,EQ12)>0,SUM(EO12,EQ12),"-") -> - | EZ12: =IFERROR(IF(FA12>0,CALC!AR12/FA12,"-"),"-") -> - | FA12: =IF(EW12>0,IFERROR(IF(CALC!AQ12>0,CALC!AQ12-EW12,"-"),"-"),"-") -> - | FB12: =IF(SUM(EV12,EX12)>0,SUM(EV12,EX12),"-") -> - | FG12: =IFERROR(IF(FH12>0,CALC!AT12/FH12,"-"),"-") -> - | FH12: =IF(FD12>0,IFERROR(IF(CALC!AS12>0,CALC!AS12-FD12,"-"),"-"),"-") -> - | FI12: =IF(SUM(FC12,FE12)>0,SUM(FC12,FE12),"-") -> - | FN12: =IFERROR(IF(FO12>0,CALC!AV12/FO12,"-"),"-") -> - | FO12: =IF(FK12>0,IFERROR(IF(CALC!AU12>0,CALC!AU12-FK12,"-"),"-"),"-") -> - | FP12: =IF(SUM(FJ12,FL12)>0,SUM(FJ12,FL12),"-") -> - | FU12: =IFERROR(IF(FV12>0,CALC!AX12/FV12,"-"),"-") -> - | FV12: =IF(FR12>0,IFERROR(IF(CALC!AW12>0,CALC!AW12-FR12,"-"),"-"),"-") -> - | FW12: =IF(SUM(FQ12,FS12)>0,SUM(FQ12,FS12),"-") -> - | GB12: =IFERROR(IF(GC12>0,CALC!AZ12/GC12,"-"),"-") -> - | GC12: =IF(FY12>0,IFERROR(IF(CALC!AY12>0,CALC!AY12-FY12,"-"),"-"),"-") -> - | GD12: =IF(SUM(FX12,FZ12)>0,SUM(FX12,FZ12),"-") -> - | GI12: =IFERROR(IF(GJ12>0,CALC!BB12/GJ12,"-"),"-") -> - | GJ12: =IF(GF12>0,IFERROR(IF(CALC!BA12>0,CALC!BA12-GF12,"-"),"-"),"-") -> - | GK12: =IF(SUM(GE12,GG12)>0,SUM(GE12,GG12),"-") -> - | GP12: =IFERROR(IF(GQ12>0,CALC!BD12/GQ12,"-"),"-") -> - | GQ12: =IF(GM12>0,IFERROR(IF(CALC!BC12>0,CALC!BC12-GM12,"-"),"-"),"-") -> - | GR12: =IF(SUM(GL12,GN12)>0,SUM(GL12,GN12),"-") -> - | GW12: =IFERROR(IF(GX12>0,CALC!BF12/GX12,"-"),"-") -> - | GX12: =IF(GT12>0,IFERROR(IF(CALC!BE12>0,CALC!BE12-GT12,"-"),"-"),"-") -> - | GY12: =IF(SUM(GS12,GU12)>0,SUM(GS12,GU12),"-") -> - | HD12: =IFERROR(IF(HE12>0,CALC!BH12/HE12,"-"),"-") -> - | HE12: =IF(HA12>0,IFERROR(IF(CALC!BG12>0,CALC!BG12-HA12,"-"),"-"),"-") -> - | HF12: =IF(SUM(GZ12,HB12)>0,SUM(GZ12,HB12),"-") -> - | HK12: =IFERROR(IF(HL12>0,CALC!BJ12/HL12,"-"),"-") -> - | HL12: =IF(HH12>0,IFERROR(IF(CALC!BI12>0,CALC!BI12-HH12,"-"),"-"),"-") -> - | HM12: =IF(SUM(HG12,HI12)>0,SUM(HG12,HI12),"-") -> - | HN12: =SUM(K12,R12,Y12,AF12,AM12,AT12,BA12,BH12,BO12,BV12,CC12,CJ12,CQ12,CX12,DE12,DL12,DS12,DZ12,EG12,EN12,EU12,FB12,FI12,FP12,FW12,GD12,GK12,GR12,GY12,HF12,HM12) -> 1550 | HO12: =SUM(J12,Q12,X12,AE12,AL12,AS12,AZ12,BG12,BN12,BU12,CB12,CI12,CP12,CW12,DD12,DK12,DR12,DY12,EF12,EM12,ET12,FA12,FH12,FO12,FV12,GC12,GJ12,GQ12,GX12,HE12,HL12) -> 28.9 | HP12: =IFERROR(HN12/HO12,"") -> 53.633218
HN13: =SUM(K13,R13,Y13,AF13,AM13,AT13,BA13,BH13,BO13,BV13,CC13,CJ13,CQ13,CX13,DE13,DL13,DS13,DZ13,EG13,EN13,EU13,FB13,FI13,FP13,FW13,GD13,GK13,GR13) -> 0 | HO13: =SUM(J13,Q13,X13,AE13,AL13,AS13,AZ13,BG13,BN13,BU13,CB13,CI13,CP13,CW13,DD13,DK13,DR13,DY13,EF13,EM13,ET13,FA13,FH13,FO13,FV13,GC13,GJ13,GQ13) -> 0 | HP13: =IFERROR(HN13/HO13,"")
C14: Alat Angkut | D14: DC 07 | I14: =IFERROR(IF(J14>0,CALC!B14/J14,"-"),"-") -> - | J14: =IF(F14>0,IFERROR(IF(CALC!A14>0,CALC!A14-F14,"-"),"-"),"-") -> - | K14: =IF(SUM(E14,G14)>0,SUM(E14,G14),"-") -> - | P14: =IFERROR(IF(Q14>0,CALC!D14/Q14,"-"),"-") -> - | Q14: =IF(M14>0,IFERROR(IF(CALC!C14>0,CALC!C14-M14,"-"),"-"),"-") -> - | R14: =IF(SUM(L14,N14)>0,SUM(L14,N14),"-") -> - | W14: =IFERROR(IF(X14>0,CALC!F14/X14,"-"),"-") -> - | X14: =IF(T14>0,IFERROR(IF(CALC!E14>0,CALC!E14-T14,"-"),"-"),"-") -> - | Y14: =IF(SUM(S14,U14)>0,SUM(S14,U14),"-") -> - | AD14: =IFERROR(IF(AE14>0,CALC!H14/AE14,"-"),"-") -> - | AE14: =IF(AA14>0,IFERROR(IF(CALC!G14>0,CALC!G14-AA14,"-"),"-"),"-") -> - | AF14: =IF(SUM(Z14,AB14)>0,SUM(Z14,AB14),"-") -> - | AK14: =IFERROR(IF(AL14>0,CALC!J14/AL14,"-"),"-") -> - | AL14: =IF(AH14>0,IFERROR(IF(CALC!I14>0,CALC!I14-AH14,"-"),"-"),"-") -> - | AM14: =IF(SUM(AG14,AI14)>0,SUM(AG14,AI14),"-") -> - | AR14: =IFERROR(IF(AS14>0,CALC!L14/AS14,"-"),"-") -> - | AS14: =IF(AO14>0,IFERROR(IF(CALC!K14>0,CALC!K14-AO14,"-"),"-"),"-") -> - | AT14: =IF(SUM(AN14,AP14)>0,SUM(AN14,AP14),"-") -> - | AY14: =IFERROR(IF(AZ14>0,CALC!N14/AZ14,"-"),"-") -> - | AZ14: =IF(AV14>0,IFERROR(IF(CALC!M14>0,CALC!M14-AV14,"-"),"-"),"-") -> - | BA14: =IF(SUM(AU14,AW14)>0,SUM(AU14,AW14),"-") -> - | BF14: =IFERROR(IF(BG14>0,CALC!P14/BG14,"-"),"-") -> - | BG14: =IF(BC14>0,IFERROR(IF(CALC!O14>0,CALC!O14-BC14,"-"),"-"),"-") -> - | BH14: =IF(SUM(BB14,BD14)>0,SUM(BB14,BD14),"-") -> - | BM14: =IFERROR(IF(BN14>0,CALC!R14/BN14,"-"),"-") -> - | BN14: =IF(BJ14>0,IFERROR(IF(CALC!Q14>0,CALC!Q14-BJ14,"-"),"-"),"-") -> - | BO14: =IF(SUM(BI14,BK14)>0,SUM(BI14,BK14),"-") -> - | BT14: =IFERROR(IF(BU14>0,CALC!T14/BU14,"-"),"-") -> - | BU14: =IF(BQ14>0,IFERROR(IF(CALC!S14>0,CALC!S14-BQ14,"-"),"-"),"-") -> - | BV14: =IF(SUM(BP14,BR14)>0,SUM(BP14,BR14),"-") -> - | CA14: =IFERROR(IF(CB14>0,CALC!V14/CB14,"-"),"-") -> - | CB14: =IF(BX14>0,IFERROR(IF(CALC!U14>0,CALC!U14-BX14,"-"),"-"),"-") -> - | CC14: =IF(SUM(BW14,BY14)>0,SUM(BW14,BY14),"-") -> - | CH14: =IFERROR(IF(CI14>0,CALC!X14/CI14,"-"),"-") -> - | CI14: =IF(CE14>0,IFERROR(IF(CALC!W14>0,CALC!W14-CE14,"-"),"-"),"-") -> - | CJ14: =IF(SUM(CD14,CF14)>0,SUM(CD14,CF14),"-") -> - | CO14: =IFERROR(IF(CP14>0,CALC!Z14/CP14,"-"),"-") -> - | CP14: =IF(CL14>0,IFERROR(IF(CALC!Y14>0,CALC!Y14-CL14,"-"),"-"),"-") -> - | CQ14: =IF(SUM(CK14,CM14)>0,SUM(CK14,CM14),"-") -> - | CV14: =IFERROR(IF(CW14>0,CALC!AB14/CW14,"-"),"-") -> - | CW14: =IF(CS14>0,IFERROR(IF(CALC!AA14>0,CALC!AA14-CS14,"-"),"-"),"-") -> - | CX14: =IF(SUM(CR14,CT14)>0,SUM(CR14,CT14),"-") -> - | DC14: =IFERROR(IF(DD14>0,CALC!AD14/DD14,"-"),"-") -> - | DD14: =IF(CZ14>0,IFERROR(IF(CALC!AC14>0,CALC!AC14-CZ14,"-"),"-"),"-") -> - | DE14: =IF(SUM(CY14,DA14)>0,SUM(CY14,DA14),"-") -> - | DJ14: =IFERROR(IF(DK14>0,CALC!AF14/DK14,"-"),"-") -> - | DK14: =IF(DG14>0,IFERROR(IF(CALC!AE14>0,CALC!AE14-DG14,"-"),"-"),"-") -> - | DL14: =IF(SUM(DF14,DH14)>0,SUM(DF14,DH14),"-") -> - | DQ14: =IFERROR(IF(DR14>0,CALC!AH14/DR14,"-"),"-") -> - | DR14: =IF(DN14>0,IFERROR(IF(CALC!AG14>0,CALC!AG14-DN14,"-"),"-"),"-") -> - | DS14: =IF(SUM(DM14,DO14)>0,SUM(DM14,DO14),"-") -> - | DX14: =IFERROR(IF(DY14>0,CALC!AJ14/DY14,"-"),"-") -> - | DY14: =IF(DU14>0,IFERROR(IF(CALC!AI14>0,CALC!AI14-DU14,"-"),"-"),"-") -> - | DZ14: =IF(SUM(DT14,DV14)>0,SUM(DT14,DV14),"-") -> - | EE14: =IFERROR(IF(EF14>0,CALC!AL14/EF14,"-"),"-") -> - | EF14: =IF(EB14>0,IFERROR(IF(CALC!AK14>0,CALC!AK14-EB14,"-"),"-"),"-") -> - | EG14: =IF(SUM(EA14,EC14)>0,SUM(EA14,EC14),"-") -> - | EL14: =IFERROR(IF(EM14>0,CALC!AN14/EM14,"-"),"-") -> - | EM14: =IF(EI14>0,IFERROR(IF(CALC!AM14>0,CALC!AM14-EI14,"-"),"-"),"-") -> - | EN14: =IF(SUM(EH14,EJ14)>0,SUM(EH14,EJ14),"-") -> - | ES14: =IFERROR(IF(ET14>0,CALC!AP14/ET14,"-"),"-") -> - | ET14: =IF(EP14>0,IFERROR(IF(CALC!AO14>0,CALC!AO14-EP14,"-"),"-"),"-") -> - | EU14: =IF(SUM(EO14,EQ14)>0,SUM(EO14,EQ14),"-") -> - | EZ14: =IFERROR(IF(FA14>0,CALC!AR14/FA14,"-"),"-") -> - | FA14: =IF(EW14>0,IFERROR(IF(CALC!AQ14>0,CALC!AQ14-EW14,"-"),"-"),"-") -> - | FB14: =IF(SUM(EV14,EX14)>0,SUM(EV14,EX14),"-") -> - | FG14: =IFERROR(IF(FH14>0,CALC!AT14/FH14,"-"),"-") -> - | FH14: =IF(FD14>0,IFERROR(IF(CALC!AS14>0,CALC!AS14-FD14,"-"),"-"),"-") -> - | FI14: =IF(SUM(FC14,FE14)>0,SUM(FC14,FE14),"-") -> - | FN14: =IFERROR(IF(FO14>0,CALC!AV14/FO14,"-"),"-") -> - | FO14: =IF(FK14>0,IFERROR(IF(CALC!AU14>0,CALC!AU14-FK14,"-"),"-"),"-") -> - | FP14: =IF(SUM(FJ14,FL14)>0,SUM(FJ14,FL14),"-") -> - | FU14: =IFERROR(IF(FV14>0,CALC!AX14/FV14,"-"),"-") -> - | FV14: =IF(FR14>0,IFERROR(IF(CALC!AW14>0,CALC!AW14-FR14,"-"),"-"),"-") -> - | FW14: =IF(SUM(FQ14,FS14)>0,SUM(FQ14,FS14),"-") -> - | GB14: =IFERROR(IF(GC14>0,CALC!AZ14/GC14,"-"),"-") -> - | GC14: =IF(FY14>0,IFERROR(IF(CALC!AY14>0,CALC!AY14-FY14,"-"),"-"),"-") -> - | GD14: =IF(SUM(FX14,FZ14)>0,SUM(FX14,FZ14),"-") -> - | GI14: =IFERROR(IF(GJ14>0,CALC!BB14/GJ14,"-"),"-") -> - | GJ14: =IF(GF14>0,IFERROR(IF(CALC!BA14>0,CALC!BA14-GF14,"-"),"-"),"-") -> - | GK14: =IF(SUM(GE14,GG14)>0,SUM(GE14,GG14),"-") -> - | GP14: =IFERROR(IF(GQ14>0,CALC!BD14/GQ14,"-"),"-") -> - | GQ14: =IF(GM14>0,IFERROR(IF(CALC!BC14>0,CALC!BC14-GM14,"-"),"-"),"-") -> - | GR14: =IF(SUM(GL14,GN14)>0,SUM(GL14,GN14),"-") -> - | GW14: =IFERROR(IF(GX14>0,CALC!BF14/GX14,"-"),"-") -> - | GX14: =IF(GT14>0,IFERROR(IF(CALC!BE14>0,CALC!BE14-GT14,"-"),"-"),"-") -> - | GY14: =IF(SUM(GS14,GU14)>0,SUM(GS14,GU14),"-") -> - | HD14: =IFERROR(IF(HE14>0,CALC!BH14/HE14,"-"),"-") -> - | HE14: =IF(HA14>0,IFERROR(IF(CALC!BG14>0,CALC!BG14-HA14,"-"),"-"),"-") -> - | HF14: =IF(SUM(GZ14,HB14)>0,SUM(GZ14,HB14),"-") -> - | HK14: =IFERROR(IF(HL14>0,CALC!BJ14/HL14,"-"),"-") -> - | HL14: =IF(HH14>0,IFERROR(IF(CALC!BI14>0,CALC!BI14-HH14,"-"),"-"),"-") -> - | HM14: =IF(SUM(HG14,HI14)>0,SUM(HG14,HI14),"-") -> - | HN14: =SUM(K14,R14,Y14,AF14,AM14,AT14,BA14,BH14,BO14,BV14,CC14,CJ14,CQ14,CX14,DE14,DL14,DS14,DZ14,EG14,EN14,EU14,FB14,FI14,FP14,FW14,GD14,GK14,GR14,GY14,HF14,HM14) -> 0 | HO14: =SUM(J14,Q14,X14,AE14,AL14,AS14,AZ14,BG14,BN14,BU14,CB14,CI14,CP14,CW14,DD14,DK14,DR14,DY14,EF14,EM14,ET14,FA14,FH14,FO14,FV14,GC14,GJ14,GQ14,GX14,HE14,HL14) -> 0 | HP14: =IFERROR(HN14/HO14,"")
D15: DC 08 | I15: =IFERROR(IF(J15>0,CALC!B15/J15,"-"),"-") -> - | J15: =IF(F15>0,IFERROR(IF(CALC!A15>0,CALC!A15-F15,"-"),"-"),"-") -> - | K15: =IF(SUM(E15,G15)>0,SUM(E15,G15),"-") -> - | P15: =IFERROR(IF(Q15>0,CALC!D15/Q15,"-"),"-") -> - | Q15: =IF(M15>0,IFERROR(IF(CALC!C15>0,CALC!C15-M15,"-"),"-"),"-") -> - | R15: =IF(SUM(L15,N15)>0,SUM(L15,N15),"-") -> - | W15: =IFERROR(IF(X15>0,CALC!F15/X15,"-"),"-") -> - | X15: =IF(T15>0,IFERROR(IF(CALC!E15>0,CALC!E15-T15,"-"),"-"),"-") -> - | Y15: =IF(SUM(S15,U15)>0,SUM(S15,U15),"-") -> - | AD15: =IFERROR(IF(AE15>0,CALC!H15/AE15,"-"),"-") -> - | AE15: =IF(AA15>0,IFERROR(IF(CALC!G15>0,CALC!G15-AA15,"-"),"-"),"-") -> - | AF15: =IF(SUM(Z15,AB15)>0,SUM(Z15,AB15),"-") -> - | AK15: =IFERROR(IF(AL15>0,CALC!J15/AL15,"-"),"-") -> - | AL15: =IF(AH15>0,IFERROR(IF(CALC!I15>0,CALC!I15-AH15,"-"),"-"),"-") -> - | AM15: =IF(SUM(AG15,AI15)>0,SUM(AG15,AI15),"-") -> - | AR15: =IFERROR(IF(AS15>0,CALC!L15/AS15,"-"),"-") -> - | AS15: =IF(AO15>0,IFERROR(IF(CALC!K15>0,CALC!K15-AO15,"-"),"-"),"-") -> - | AT15: =IF(SUM(AN15,AP15)>0,SUM(AN15,AP15),"-") -> - | AY15: =IFERROR(IF(AZ15>0,CALC!N15/AZ15,"-"),"-") -> - | AZ15: =IF(AV15>0,IFERROR(IF(CALC!M15>0,CALC!M15-AV15,"-"),"-"),"-") -> - | BA15: =IF(SUM(AU15,AW15)>0,SUM(AU15,AW15),"-") -> - | BF15: =IFERROR(IF(BG15>0,CALC!P15/BG15,"-"),"-") -> - | BG15: =IF(BC15>0,IFERROR(IF(CALC!O15>0,CALC!O15-BC15,"-"),"-"),"-") -> - | BH15: =IF(SUM(BB15,BD15)>0,SUM(BB15,BD15),"-") -> - | BM15: =IFERROR(IF(BN15>0,CALC!R15/BN15,"-"),"-") -> - | BN15: =IF(BJ15>0,IFERROR(IF(CALC!Q15>0,CALC!Q15-BJ15,"-"),"-"),"-") -> - | BO15: =IF(SUM(BI15,BK15)>0,SUM(BI15,BK15),"-") -> - | BT15: =IFERROR(IF(BU15>0,CALC!T15/BU15,"-"),"-") -> - | BU15: =IF(BQ15>0,IFERROR(IF(CALC!S15>0,CALC!S15-BQ15,"-"),"-"),"-") -> - | BV15: =IF(SUM(BP15,BR15)>0,SUM(BP15,BR15),"-") -> - | CA15: =IFERROR(IF(CB15>0,CALC!V15/CB15,"-"),"-") -> - | CB15: =IF(BX15>0,IFERROR(IF(CALC!U15>0,CALC!U15-BX15,"-"),"-"),"-") -> - | CC15: =IF(SUM(BW15,BY15)>0,SUM(BW15,BY15),"-") -> - | CH15: =IFERROR(IF(CI15>0,CALC!X15/CI15,"-"),"-") -> - | CI15: =IF(CE15>0,IFERROR(IF(CALC!W15>0,CALC!W15-CE15,"-"),"-"),"-") -> - | CJ15: =IF(SUM(CD15,CF15)>0,SUM(CD15,CF15),"-") -> - | CO15: =IFERROR(IF(CP15>0,CALC!Z15/CP15,"-"),"-") -> - | CP15: =IF(CL15>0,IFERROR(IF(CALC!Y15>0,CALC!Y15-CL15,"-"),"-"),"-") -> - | CQ15: =IF(SUM(CK15,CM15)>0,SUM(CK15,CM15),"-") -> - | CV15: =IFERROR(IF(CW15>0,CALC!AB15/CW15,"-"),"-") -> - | CW15: =IF(CS15>0,IFERROR(IF(CALC!AA15>0,CALC!AA15-CS15,"-"),"-"),"-") -> - | CX15: =IF(SUM(CR15,CT15)>0,SUM(CR15,CT15),"-") -> - | DC15: =IFERROR(IF(DD15>0,CALC!AD15/DD15,"-"),"-") -> - | DD15: =IF(CZ15>0,IFERROR(IF(CALC!AC15>0,CALC!AC15-CZ15,"-"),"-"),"-") -> - | DE15: =IF(SUM(CY15,DA15)>0,SUM(CY15,DA15),"-") -> - | DJ15: =IFERROR(IF(DK15>0,CALC!AF15/DK15,"-"),"-") -> - | DK15: =IF(DG15>0,IFERROR(IF(CALC!AE15>0,CALC!AE15-DG15,"-"),"-"),"-") -> - | DL15: =IF(SUM(DF15,DH15)>0,SUM(DF15,DH15),"-") -> - | DQ15: =IFERROR(IF(DR15>0,CALC!AH15/DR15,"-"),"-") -> - | DR15: =IF(DN15>0,IFERROR(IF(CALC!AG15>0,CALC!AG15-DN15,"-"),"-"),"-") -> - | DS15: =IF(SUM(DM15,DO15)>0,SUM(DM15,DO15),"-") -> - | DX15: =IFERROR(IF(DY15>0,CALC!AJ15/DY15,"-"),"-") -> - | DY15: =IF(DU15>0,IFERROR(IF(CALC!AI15>0,CALC!AI15-DU15,"-"),"-"),"-") -> - | DZ15: =IF(SUM(DT15,DV15)>0,SUM(DT15,DV15),"-") -> - | EE15: =IFERROR(IF(EF15>0,CALC!AL15/EF15,"-"),"-") -> - | EF15: =IF(EB15>0,IFERROR(IF(CALC!AK15>0,CALC!AK15-EB15,"-"),"-"),"-") -> - | EG15: =IF(SUM(EA15,EC15)>0,SUM(EA15,EC15),"-") -> - | EL15: =IFERROR(IF(EM15>0,CALC!AN15/EM15,"-"),"-") -> - | EM15: =IF(EI15>0,IFERROR(IF(CALC!AM15>0,CALC!AM15-EI15,"-"),"-"),"-") -> - | EN15: =IF(SUM(EH15,EJ15)>0,SUM(EH15,EJ15),"-") -> - | ES15: =IFERROR(IF(ET15>0,CALC!AP15/ET15,"-"),"-") -> - | ET15: =IF(EP15>0,IFERROR(IF(CALC!AO15>0,CALC!AO15-EP15,"-"),"-"),"-") -> - | EU15: =IF(SUM(EO15,EQ15)>0,SUM(EO15,EQ15),"-") -> - | EZ15: =IFERROR(IF(FA15>0,CALC!AR15/FA15,"-"),"-") -> - | FA15: =IF(EW15>0,IFERROR(IF(CALC!AQ15>0,CALC!AQ15-EW15,"-"),"-"),"-") -> - | FB15: =IF(SUM(EV15,EX15)>0,SUM(EV15,EX15),"-") -> - | FG15: =IFERROR(IF(FH15>0,CALC!AT15/FH15,"-"),"-") -> - | FH15: =IF(FD15>0,IFERROR(IF(CALC!AS15>0,CALC!AS15-FD15,"-"),"-"),"-") -> - | FI15: =IF(SUM(FC15,FE15)>0,SUM(FC15,FE15),"-") -> - | FN15: =IFERROR(IF(FO15>0,CALC!AV15/FO15,"-"),"-") -> - | FO15: =IF(FK15>0,IFERROR(IF(CALC!AU15>0,CALC!AU15-FK15,"-"),"-"),"-") -> - | FP15: =IF(SUM(FJ15,FL15)>0,SUM(FJ15,FL15),"-") -> - | FU15: =IFERROR(IF(FV15>0,CALC!AX15/FV15,"-"),"-") -> - | FV15: =IF(FR15>0,IFERROR(IF(CALC!AW15>0,CALC!AW15-FR15,"-"),"-"),"-") -> - | FW15: =IF(SUM(FQ15,FS15)>0,SUM(FQ15,FS15),"-") -> - | GB15: =IFERROR(IF(GC15>0,CALC!AZ15/GC15,"-"),"-") -> - | GC15: =IF(FY15>0,IFERROR(IF(CALC!AY15>0,CALC!AY15-FY15,"-"),"-"),"-") -> - | GD15: =IF(SUM(FX15,FZ15)>0,SUM(FX15,FZ15),"-") -> - | GI15: =IFERROR(IF(GJ15>0,CALC!BB15/GJ15,"-"),"-") -> - | GJ15: =IF(GF15>0,IFERROR(IF(CALC!BA15>0,CALC!BA15-GF15,"-"),"-"),"-") -> - | GK15: =IF(SUM(GE15,GG15)>0,SUM(GE15,GG15),"-") -> - | GP15: =IFERROR(IF(GQ15>0,CALC!BD15/GQ15,"-"),"-") -> - | GQ15: =IF(GM15>0,IFERROR(IF(CALC!BC15>0,CALC!BC15-GM15,"-"),"-"),"-") -> - | GR15: =IF(SUM(GL15,GN15)>0,SUM(GL15,GN15),"-") -> - | GW15: =IFERROR(IF(GX15>0,CALC!BF15/GX15,"-"),"-") -> - | GX15: =IF(GT15>0,IFERROR(IF(CALC!BE15>0,CALC!BE15-GT15,"-"),"-"),"-") -> - | GY15: =IF(SUM(GS15,GU15)>0,SUM(GS15,GU15),"-") -> - | HD15: =IFERROR(IF(HE15>0,CALC!BH15/HE15,"-"),"-") -> - | HE15: =IF(HA15>0,IFERROR(IF(CALC!BG15>0,CALC!BG15-HA15,"-"),"-"),"-") -> - | HF15: =IF(SUM(GZ15,HB15)>0,SUM(GZ15,HB15),"-") -> - | HK15: =IFERROR(IF(HL15>0,CALC!BJ15/HL15,"-"),"-") -> - | HL15: =IF(HH15>0,IFERROR(IF(CALC!BI15>0,CALC!BI15-HH15,"-"),"-"),"-") -> - | HM15: =IF(SUM(HG15,HI15)>0,SUM(HG15,HI15),"-") -> - | HN15: =SUM(K15,R15,Y15,AF15,AM15,AT15,BA15,BH15,BO15,BV15,CC15,CJ15,CQ15,CX15,DE15,DL15,DS15,DZ15,EG15,EN15,EU15,FB15,FI15,FP15,FW15,GD15,GK15,GR15,GY15,HF15,HM15) -> 0 | HO15: =SUM(J15,Q15,X15,AE15,AL15,AS15,AZ15,BG15,BN15,BU15,CB15,CI15,CP15,CW15,DD15,DK15,DR15,DY15,EF15,EM15,ET15,FA15,FH15,FO15,FV15,GC15,GJ15,GQ15,GX15,HE15,HL15) -> 0 | HP15: =IFERROR(HN15/HO15,"")
D16: DC 09 | I16: =IFERROR(IF(J16>0,CALC!B16/J16,"-"),"-") -> - | J16: =IF(F16>0,IFERROR(IF(CALC!A16>0,CALC!A16-F16,"-"),"-"),"-") -> - | K16: =IF(SUM(E16,G16)>0,SUM(E16,G16),"-") -> - | P16: =IFERROR(IF(Q16>0,CALC!D16/Q16,"-"),"-") -> - | Q16: =IF(M16>0,IFERROR(IF(CALC!C16>0,CALC!C16-M16,"-"),"-"),"-") -> - | R16: =IF(SUM(L16,N16)>0,SUM(L16,N16),"-") -> - | W16: =IFERROR(IF(X16>0,CALC!F16/X16,"-"),"-") -> - | X16: =IF(T16>0,IFERROR(IF(CALC!E16>0,CALC!E16-T16,"-"),"-"),"-") -> - | Y16: =IF(SUM(S16,U16)>0,SUM(S16,U16),"-") -> - | AD16: =IFERROR(IF(AE16>0,CALC!H16/AE16,"-"),"-") -> - | AE16: =IF(AA16>0,IFERROR(IF(CALC!G16>0,CALC!G16-AA16,"-"),"-"),"-") -> - | AF16: =IF(SUM(Z16,AB16)>0,SUM(Z16,AB16),"-") -> - | AK16: =IFERROR(IF(AL16>0,CALC!J16/AL16,"-"),"-") -> - | AL16: =IF(AH16>0,IFERROR(IF(CALC!I16>0,CALC!I16-AH16,"-"),"-"),"-") -> - | AM16: =IF(SUM(AG16,AI16)>0,SUM(AG16,AI16),"-") -> - | AR16: =IFERROR(IF(AS16>0,CALC!L16/AS16,"-"),"-") -> - | AS16: =IF(AO16>0,IFERROR(IF(CALC!K16>0,CALC!K16-AO16,"-"),"-"),"-") -> - | AT16: =IF(SUM(AN16,AP16)>0,SUM(AN16,AP16),"-") -> - | AY16: =IFERROR(IF(AZ16>0,CALC!N16/AZ16,"-"),"-") -> - | AZ16: =IF(AV16>0,IFERROR(IF(CALC!M16>0,CALC!M16-AV16,"-"),"-"),"-") -> - | BA16: =IF(SUM(AU16,AW16)>0,SUM(AU16,AW16),"-") -> - | BF16: =IFERROR(IF(BG16>0,CALC!P16/BG16,"-"),"-") -> - | BG16: =IF(BC16>0,IFERROR(IF(CALC!O16>0,CALC!O16-BC16,"-"),"-"),"-") -> - | BH16: =IF(SUM(BB16,BD16)>0,SUM(BB16,BD16),"-") -> - | BM16: =IFERROR(IF(BN16>0,CALC!R16/BN16,"-"),"-") -> - | BN16: =IF(BJ16>0,IFERROR(IF(CALC!Q16>0,CALC!Q16-BJ16,"-"),"-"),"-") -> - | BO16: =IF(SUM(BI16,BK16)>0,SUM(BI16,BK16),"-") -> - | BT16: =IFERROR(IF(BU16>0,CALC!T16/BU16,"-"),"-") -> - | BU16: =IF(BQ16>0,IFERROR(IF(CALC!S16>0,CALC!S16-BQ16,"-"),"-"),"-") -> - | BV16: =IF(SUM(BP16,BR16)>0,SUM(BP16,BR16),"-") -> - | CA16: =IFERROR(IF(CB16>0,CALC!V16/CB16,"-"),"-") -> - | CB16: =IF(BX16>0,IFERROR(IF(CALC!U16>0,CALC!U16-BX16,"-"),"-"),"-") -> - | CC16: =IF(SUM(BW16,BY16)>0,SUM(BW16,BY16),"-") -> - | CH16: =IFERROR(IF(CI16>0,CALC!X16/CI16,"-"),"-") -> - | CI16: =IF(CE16>0,IFERROR(IF(CALC!W16>0,CALC!W16-CE16,"-"),"-"),"-") -> - | CJ16: =IF(SUM(CD16,CF16)>0,SUM(CD16,CF16),"-") -> - | CO16: =IFERROR(IF(CP16>0,CALC!Z16/CP16,"-"),"-") -> - | CP16: =IF(CL16>0,IFERROR(IF(CALC!Y16>0,CALC!Y16-CL16,"-"),"-"),"-") -> - | CQ16: =IF(SUM(CK16,CM16)>0,SUM(CK16,CM16),"-") -> - | CV16: =IFERROR(IF(CW16>0,CALC!AB16/CW16,"-"),"-") -> - | CW16: =IF(CS16>0,IFERROR(IF(CALC!AA16>0,CALC!AA16-CS16,"-"),"-"),"-") -> - | CX16: =IF(SUM(CR16,CT16)>0,SUM(CR16,CT16),"-") -> - | DC16: =IFERROR(IF(DD16>0,CALC!AD16/DD16,"-"),"-") -> - | DD16: =IF(CZ16>0,IFERROR(IF(CALC!AC16>0,CALC!AC16-CZ16,"-"),"-"),"-") -> - | DE16: =IF(SUM(CY16,DA16)>0,SUM(CY16,DA16),"-") -> - | DJ16: =IFERROR(IF(DK16>0,CALC!AF16/DK16,"-"),"-") -> - | DK16: =IF(DG16>0,IFERROR(IF(CALC!AE16>0,CALC!AE16-DG16,"-"),"-"),"-") -> - | DL16: =IF(SUM(DF16,DH16)>0,SUM(DF16,DH16),"-") -> - | DQ16: =IFERROR(IF(DR16>0,CALC!AH16/DR16,"-"),"-") -> - | DR16: =IF(DN16>0,IFERROR(IF(CALC!AG16>0,CALC!AG16-DN16,"-"),"-"),"-") -> - | DS16: =IF(SUM(DM16,DO16)>0,SUM(DM16,DO16),"-") -> - | DX16: =IFERROR(IF(DY16>0,CALC!AJ16/DY16,"-"),"-") -> - | DY16: =IF(DU16>0,IFERROR(IF(CALC!AI16>0,CALC!AI16-DU16,"-"),"-"),"-") -> - | DZ16: =IF(SUM(DT16,DV16)>0,SUM(DT16,DV16),"-") -> - | EE16: =IFERROR(IF(EF16>0,CALC!AL16/EF16,"-"),"-") -> - | EF16: =IF(EB16>0,IFERROR(IF(CALC!AK16>0,CALC!AK16-EB16,"-"),"-"),"-") -> - | EG16: =IF(SUM(EA16,EC16)>0,SUM(EA16,EC16),"-") -> - | EL16: =IFERROR(IF(EM16>0,CALC!AN16/EM16,"-"),"-") -> - | EM16: =IF(EI16>0,IFERROR(IF(CALC!AM16>0,CALC!AM16-EI16,"-"),"-"),"-") -> - | EN16: =IF(SUM(EH16,EJ16)>0,SUM(EH16,EJ16),"-") -> - | ES16: =IFERROR(IF(ET16>0,CALC!AP16/ET16,"-"),"-") -> - | ET16: =IF(EP16>0,IFERROR(IF(CALC!AO16>0,CALC!AO16-EP16,"-"),"-"),"-") -> - | EU16: =IF(SUM(EO16,EQ16)>0,SUM(EO16,EQ16),"-") -> - | EZ16: =IFERROR(IF(FA16>0,CALC!AR16/FA16,"-"),"-") -> - | FA16: =IF(EW16>0,IFERROR(IF(CALC!AQ16>0,CALC!AQ16-EW16,"-"),"-"),"-") -> - | FB16: =IF(SUM(EV16,EX16)>0,SUM(EV16,EX16),"-") -> - | FG16: =IFERROR(IF(FH16>0,CALC!AT16/FH16,"-"),"-") -> - | FH16: =IF(FD16>0,IFERROR(IF(CALC!AS16>0,CALC!AS16-FD16,"-"),"-"),"-") -> - | FI16: =IF(SUM(FC16,FE16)>0,SUM(FC16,FE16),"-") -> - | FN16: =IFERROR(IF(FO16>0,CALC!AV16/FO16,"-"),"-") -> - | FO16: =IF(FK16>0,IFERROR(IF(CALC!AU16>0,CALC!AU16-FK16,"-"),"-"),"-") -> - | FP16: =IF(SUM(FJ16,FL16)>0,SUM(FJ16,FL16),"-") -> - | FU16: =IFERROR(IF(FV16>0,CALC!AX16/FV16,"-"),"-") -> - | FV16: =IF(FR16>0,IFERROR(IF(CALC!AW16>0,CALC!AW16-FR16,"-"),"-"),"-") -> - | FW16: =IF(SUM(FQ16,FS16)>0,SUM(FQ16,FS16),"-") -> - | GB16: =IFERROR(IF(GC16>0,CALC!AZ16/GC16,"-"),"-") -> - | GC16: =IF(FY16>0,IFERROR(IF(CALC!AY16>0,CALC!AY16-FY16,"-"),"-"),"-") -> - | GD16: =IF(SUM(FX16,FZ16)>0,SUM(FX16,FZ16),"-") -> - | GI16: =IFERROR(IF(GJ16>0,CALC!BB16/GJ16,"-"),"-") -> - | GJ16: =IF(GF16>0,IFERROR(IF(CALC!BA16>0,CALC!BA16-GF16,"-"),"-"),"-") -> - | GK16: =IF(SUM(GE16,GG16)>0,SUM(GE16,GG16),"-") -> - | GP16: =IFERROR(IF(GQ16>0,CALC!BD16/GQ16,"-"),"-") -> - | GQ16: =IF(GM16>0,IFERROR(IF(CALC!BC16>0,CALC!BC16-GM16,"-"),"-"),"-") -> - | GR16: =IF(SUM(GL16,GN16)>0,SUM(GL16,GN16),"-") -> - | GW16: =IFERROR(IF(GX16>0,CALC!BF16/GX16,"-"),"-") -> - | GX16: =IF(GT16>0,IFERROR(IF(CALC!BE16>0,CALC!BE16-GT16,"-"),"-"),"-") -> - | GY16: =IF(SUM(GS16,GU16)>0,SUM(GS16,GU16),"-") -> - | HD16: =IFERROR(IF(HE16>0,CALC!BH16/HE16,"-"),"-") -> - | HE16: =IF(HA16>0,IFERROR(IF(CALC!BG16>0,CALC!BG16-HA16,"-"),"-"),"-") -> - | HF16: =IF(SUM(GZ16,HB16)>0,SUM(GZ16,HB16),"-") -> - | HK16: =IFERROR(IF(HL16>0,CALC!BJ16/HL16,"-"),"-") -> - | HL16: =IF(HH16>0,IFERROR(IF(CALC!BI16>0,CALC!BI16-HH16,"-"),"-"),"-") -> - | HM16: =IF(SUM(HG16,HI16)>0,SUM(HG16,HI16),"-") -> - | HN16: =SUM(K16,R16,Y16,AF16,AM16,AT16,BA16,BH16,BO16,BV16,CC16,CJ16,CQ16,CX16,DE16,DL16,DS16,DZ16,EG16,EN16,EU16,FB16,FI16,FP16,FW16,GD16,GK16,GR16,GY16,HF16,HM16) -> 0 | HO16: =SUM(J16,Q16,X16,AE16,AL16,AS16,AZ16,BG16,BN16,BU16,CB16,CI16,CP16,CW16,DD16,DK16,DR16,DY16,EF16,EM16,ET16,FA16,FH16,FO16,FV16,GC16,GJ16,GQ16,GX16,HE16,HL16) -> 0 | HP16: =IFERROR(HN16/HO16,"")
D17: DC 10 | I17: =IFERROR(IF(J17>0,CALC!B17/J17,"-"),"-") -> - | J17: =IF(F17>0,IFERROR(IF(CALC!A17>0,CALC!A17-F17,"-"),"-"),"-") -> - | K17: =IF(SUM(E17,G17)>0,SUM(E17,G17),"-") -> - | P17: =IFERROR(IF(Q17>0,CALC!D17/Q17,"-"),"-") -> - | Q17: =IF(M17>0,IFERROR(IF(CALC!C17>0,CALC!C17-M17,"-"),"-"),"-") -> - | R17: =IF(SUM(L17,N17)>0,SUM(L17,N17),"-") -> - | W17: =IFERROR(IF(X17>0,CALC!F17/X17,"-"),"-") -> - | X17: =IF(T17>0,IFERROR(IF(CALC!E17>0,CALC!E17-T17,"-"),"-"),"-") -> - | Y17: =IF(SUM(S17,U17)>0,SUM(S17,U17),"-") -> - | AD17: =IFERROR(IF(AE17>0,CALC!H17/AE17,"-"),"-") -> - | AE17: =IF(AA17>0,IFERROR(IF(CALC!G17>0,CALC!G17-AA17,"-"),"-"),"-") -> - | AF17: =IF(SUM(Z17,AB17)>0,SUM(Z17,AB17),"-") -> - | AK17: =IFERROR(IF(AL17>0,CALC!J17/AL17,"-"),"-") -> - | AL17: =IF(AH17>0,IFERROR(IF(CALC!I17>0,CALC!I17-AH17,"-"),"-"),"-") -> - | AM17: =IF(SUM(AG17,AI17)>0,SUM(AG17,AI17),"-") -> - | AR17: =IFERROR(IF(AS17>0,CALC!L17/AS17,"-"),"-") -> - | AS17: =IF(AO17>0,IFERROR(IF(CALC!K17>0,CALC!K17-AO17,"-"),"-"),"-") -> - | AT17: =IF(SUM(AN17,AP17)>0,SUM(AN17,AP17),"-") -> - | AY17: =IFERROR(IF(AZ17>0,CALC!N17/AZ17,"-"),"-") -> - | AZ17: =IF(AV17>0,IFERROR(IF(CALC!M17>0,CALC!M17-AV17,"-"),"-"),"-") -> - | BA17: =IF(SUM(AU17,AW17)>0,SUM(AU17,AW17),"-") -> - | BF17: =IFERROR(IF(BG17>0,CALC!P17/BG17,"-"),"-") -> - | BG17: =IF(BC17>0,IFERROR(IF(CALC!O17>0,CALC!O17-BC17,"-"),"-"),"-") -> - | BH17: =IF(SUM(BB17,BD17)>0,SUM(BB17,BD17),"-") -> - | BM17: =IFERROR(IF(BN17>0,CALC!R17/BN17,"-"),"-") -> - | BN17: =IF(BJ17>0,IFERROR(IF(CALC!Q17>0,CALC!Q17-BJ17,"-"),"-"),"-") -> - | BO17: =IF(SUM(BI17,BK17)>0,SUM(BI17,BK17),"-") -> - | BT17: =IFERROR(IF(BU17>0,CALC!T17/BU17,"-"),"-") -> - | BU17: =IF(BQ17>0,IFERROR(IF(CALC!S17>0,CALC!S17-BQ17,"-"),"-"),"-") -> - | BV17: =IF(SUM(BP17,BR17)>0,SUM(BP17,BR17),"-") -> - | CA17: =IFERROR(IF(CB17>0,CALC!V17/CB17,"-"),"-") -> - | CB17: =IF(BX17>0,IFERROR(IF(CALC!U17>0,CALC!U17-BX17,"-"),"-"),"-") -> - | CC17: =IF(SUM(BW17,BY17)>0,SUM(BW17,BY17),"-") -> - | CH17: =IFERROR(IF(CI17>0,CALC!X17/CI17,"-"),"-") -> - | CI17: =IF(CE17>0,IFERROR(IF(CALC!W17>0,CALC!W17-CE17,"-"),"-"),"-") -> - | CJ17: =IF(SUM(CD17,CF17)>0,SUM(CD17,CF17),"-") -> - | CO17: =IFERROR(IF(CP17>0,CALC!Z17/CP17,"-"),"-") -> - | CP17: =IF(CL17>0,IFERROR(IF(CALC!Y17>0,CALC!Y17-CL17,"-"),"-"),"-") -> - | CQ17: =IF(SUM(CK17,CM17)>0,SUM(CK17,CM17),"-") -> - | CV17: =IFERROR(IF(CW17>0,CALC!AB17/CW17,"-"),"-") -> - | CW17: =IF(CS17>0,IFERROR(IF(CALC!AA17>0,CALC!AA17-CS17,"-"),"-"),"-") -> - | CX17: =IF(SUM(CR17,CT17)>0,SUM(CR17,CT17),"-") -> - | DC17: =IFERROR(IF(DD17>0,CALC!AD17/DD17,"-"),"-") -> - | DD17: =IF(CZ17>0,IFERROR(IF(CALC!AC17>0,CALC!AC17-CZ17,"-"),"-"),"-") -> - | DE17: =IF(SUM(CY17,DA17)>0,SUM(CY17,DA17),"-") -> - | DJ17: =IFERROR(IF(DK17>0,CALC!AF17/DK17,"-"),"-") -> - | DK17: =IF(DG17>0,IFERROR(IF(CALC!AE17>0,CALC!AE17-DG17,"-"),"-"),"-") -> - | DL17: =IF(SUM(DF17,DH17)>0,SUM(DF17,DH17),"-") -> - | DQ17: =IFERROR(IF(DR17>0,CALC!AH17/DR17,"-"),"-") -> - | DR17: =IF(DN17>0,IFERROR(IF(CALC!AG17>0,CALC!AG17-DN17,"-"),"-"),"-") -> - | DS17: =IF(SUM(DM17,DO17)>0,SUM(DM17,DO17),"-") -> - | DX17: =IFERROR(IF(DY17>0,CALC!AJ17/DY17,"-"),"-") -> - | DY17: =IF(DU17>0,IFERROR(IF(CALC!AI17>0,CALC!AI17-DU17,"-"),"-"),"-") -> - | DZ17: =IF(SUM(DT17,DV17)>0,SUM(DT17,DV17),"-") -> - | EE17: =IFERROR(IF(EF17>0,CALC!AL17/EF17,"-"),"-") -> - | EF17: =IF(EB17>0,IFERROR(IF(CALC!AK17>0,CALC!AK17-EB17,"-"),"-"),"-") -> - | EG17: =IF(SUM(EA17,EC17)>0,SUM(EA17,EC17),"-") -> - | EL17: =IFERROR(IF(EM17>0,CALC!AN17/EM17,"-"),"-") -> - | EM17: =IF(EI17>0,IFERROR(IF(CALC!AM17>0,CALC!AM17-EI17,"-"),"-"),"-") -> - | EN17: =IF(SUM(EH17,EJ17)>0,SUM(EH17,EJ17),"-") -> - | ES17: =IFERROR(IF(ET17>0,CALC!AP17/ET17,"-"),"-") -> - | ET17: =IF(EP17>0,IFERROR(IF(CALC!AO17>0,CALC!AO17-EP17,"-"),"-"),"-") -> - | EU17: =IF(SUM(EO17,EQ17)>0,SUM(EO17,EQ17),"-") -> - | EZ17: =IFERROR(IF(FA17>0,CALC!AR17/FA17,"-"),"-") -> - | FA17: =IF(EW17>0,IFERROR(IF(CALC!AQ17>0,CALC!AQ17-EW17,"-"),"-"),"-") -> - | FB17: =IF(SUM(EV17,EX17)>0,SUM(EV17,EX17),"-") -> - | FG17: =IFERROR(IF(FH17>0,CALC!AT17/FH17,"-"),"-") -> - | FH17: =IF(FD17>0,IFERROR(IF(CALC!AS17>0,CALC!AS17-FD17,"-"),"-"),"-") -> - | FI17: =IF(SUM(FC17,FE17)>0,SUM(FC17,FE17),"-") -> - | FN17: =IFERROR(IF(FO17>0,CALC!AV17/FO17,"-"),"-") -> - | FO17: =IF(FK17>0,IFERROR(IF(CALC!AU17>0,CALC!AU17-FK17,"-"),"-"),"-") -> - | FP17: =IF(SUM(FJ17,FL17)>0,SUM(FJ17,FL17),"-") -> - | FU17: =IFERROR(IF(FV17>0,CALC!AX17/FV17,"-"),"-") -> - | FV17: =IF(FR17>0,IFERROR(IF(CALC!AW17>0,CALC!AW17-FR17,"-"),"-"),"-") -> - | FW17: =IF(SUM(FQ17,FS17)>0,SUM(FQ17,FS17),"-") -> - | GB17: =IFERROR(IF(GC17>0,CALC!AZ17/GC17,"-"),"-") -> - | GC17: =IF(FY17>0,IFERROR(IF(CALC!AY17>0,CALC!AY17-FY17,"-"),"-"),"-") -> - | GD17: =IF(SUM(FX17,FZ17)>0,SUM(FX17,FZ17),"-") -> - | GI17: =IFERROR(IF(GJ17>0,CALC!BB17/GJ17,"-"),"-") -> - | GJ17: =IF(GF17>0,IFERROR(IF(CALC!BA17>0,CALC!BA17-GF17,"-"),"-"),"-") -> - | GK17: =IF(SUM(GE17,GG17)>0,SUM(GE17,GG17),"-") -> - | GP17: =IFERROR(IF(GQ17>0,CALC!BD17/GQ17,"-"),"-") -> - | GQ17: =IF(GM17>0,IFERROR(IF(CALC!BC17>0,CALC!BC17-GM17,"-"),"-"),"-") -> - | GR17: =IF(SUM(GL17,GN17)>0,SUM(GL17,GN17),"-") -> - | GW17: =IFERROR(IF(GX17>0,CALC!BF17/GX17,"-"),"-") -> - | GX17: =IF(GT17>0,IFERROR(IF(CALC!BE17>0,CALC!BE17-GT17,"-"),"-"),"-") -> - | GY17: =IF(SUM(GS17,GU17)>0,SUM(GS17,GU17),"-") -> - | HD17: =IFERROR(IF(HE17>0,CALC!BH17/HE17,"-"),"-") -> - | HE17: =IF(HA17>0,IFERROR(IF(CALC!BG17>0,CALC!BG17-HA17,"-"),"-"),"-") -> - | HF17: =IF(SUM(GZ17,HB17)>0,SUM(GZ17,HB17),"-") -> - | HK17: =IFERROR(IF(HL17>0,CALC!BJ17/HL17,"-"),"-") -> - | HL17: =IF(HH17>0,IFERROR(IF(CALC!BI17>0,CALC!BI17-HH17,"-"),"-"),"-") -> - | HM17: =IF(SUM(HG17,HI17)>0,SUM(HG17,HI17),"-") -> - | HN17: =SUM(K17,R17,Y17,AF17,AM17,AT17,BA17,BH17,BO17,BV17,CC17,CJ17,CQ17,CX17,DE17,DL17,DS17,DZ17,EG17,EN17,EU17,FB17,FI17,FP17,FW17,GD17,GK17,GR17,GY17,HF17,HM17) -> 0 | HO17: =SUM(J17,Q17,X17,AE17,AL17,AS17,AZ17,BG17,BN17,BU17,CB17,CI17,CP17,CW17,DD17,DK17,DR17,DY17,EF17,EM17,ET17,FA17,FH17,FO17,FV17,GC17,GJ17,GQ17,GX17,HE17,HL17) -> 0 | HP17: =IFERROR(HN17/HO17,"")
